Workbook
Name ListeMP: 'Bibliothèque MP INRA'!$A$2:INDEX('Bibliothèque MP INRA'!$A:$A,COUNTA('Bibliothèque MP INRA'!$A:$A))

Sheet Besoins INRAE
A1: BESOINS INRAE AVANCÉS - PARAMÈTRES NUTRITIONNISTE
S2: Holstein | T2: 650 | U2: 1 | V2: Non | W2: 2 | X2: 10 | Y2: 2x | Z2: 1 | AA2: Holstein | AB2: 38.5 | AC2: Holstein | AD2: 31.2 | AE2: Holstein | AF2: 45
A3: Race | B3: Normande | S3: Montbéliarde | T3: 725 | U3: 2 | V3: Faible | W3: 3 | X3: 13 | Y3: 3x | Z3: 2 | AA3: Montbéliarde | AB3: 38.4 | AC3: Montbéliarde | AD3: 32.7 | AE3: Montbéliarde | AF3: 37
A4: Poids vif moyenne (kg) | B4: =IFERROR(VLOOKUP(B3,$S$2:$T$7,2,FALSE),"") -> 750 | S4: Normande | T4: 750 | U4: 3 | V4: Modéré | W4: 4 | X4: 16 | Y4: Robot | Z4: 3 | AA4: Normande | AB4: 41.6 | AC4: Normande | AD4: 34.2 | AE4: Normande | AF4: 31
A5: NEC / BCS (1-5) | B5: 2 | S5: Jersiaise | T5: 430 | U5: 4 | V5: Fort | W5: 5 | X5: 19 | Z5: 4 | AA5: Jersiaise | AB5: 54.5 | AC5: Jersiaise | AD5: 37.8 | AE5: Jersiaise | AF5: 27
A6: Poids vif réel (kg) | B6: =IF(B5=1,B4-80,IF(B5=2,B4-40,IF(B5=3,B4,IF(B5=4,B4+40,IF(B5=5,B4+80))))) -> 710 | S6: Brune | T6: 700 | W6: 6 | X6: 22 | Z6: 5 | AA6: Brune | AB6: 41.1 | AC6: Brune | AD6: 33.7 | AE6: Brune | AF6: 35
A7: TB estimé | B7: =IFERROR(VLOOKUP(B3,$AA2:$AB7,2,FALSE),"") -> 41.6 | S7: Simmental | T7: 750 | W7: 7 | X7: 25 | AA7: Simmental | AB7: 39.8 | AC7: Simmental | AD7: 33.6 | AE7: Simmental | AF7: 33
A8: TP estimé | B8: =IFERROR(VLOOKUP(B3,$AC2:$AD7,2,FALSE),"") -> 34.2 | W8: 8 | X8: 28
A9: Numéro lactation | B9: 3 | W9: 9 | X9: 31
A10: Facteur lactation | B10: =IF(B9=1,0.85,IF(B9=2,0.95,1)) -> 1 | X10: 34
A11: Pic race | B11: =IFERROR(VLOOKUP(B3,$AE$2:$AF$7,2,FALSE),"") -> 31
A12: DIM (jours en lait) | B12: 150
A13: Production lait réelle (L/j) | B13: 26.6
A14: TB observé | B14: 43.5
A15: TP observé | B15: 33.5
A16: MSI réelle (kg MS/j) | B16: ='Ration Formulation'!D35 -> 14.71
A17: Tri ration | B17: Non | G17: =IFERROR(VLOOKUP(B3,$AA2:$AB7,2,FALSE),"") -> 41.6
A18: Gestation | B18: 4
A19: Température ambiance | B19: 31 | C19: =IF(B21<150,"DEFICIT AZOTE",IF(B21<201,"AZOTE LIMITANTE",IF(B21<=251,"BON EQUILIBRE",IF(B21<=301,"ZONE OPTIMALE",IF(B21<=351,"EXCES LEGER OU MANQUE D'ENERGIE","DESEQUILIBRE MARQUE"))))) -> AZOTE LIMITANTE
A20: Système traite | B20: 2x
A21: Uréetest | B21: 200
A24: Besoins en eau | B24: =IF(B19<15,(4*B16)+(1*B13),IF(B19<25,(4.5*B16)+(1.2*B13),(5.5*B16)+(1.5*B13))) -> 120.805
A25: Ratio TB/TP | B25: =IFERROR(B14/B15,"") -> 1.2985075 | C25: =IF(B25<1.1,"ACIDOSE POSSIBLE",IF(B25<1.25,"EQUILIBRE CORRECT",IF(B25<1.4,"VIGILANCE ENERGETIQUE","RISQUE CETOSE"))) -> VIGILANCE ENERGETIQUE | D25: =IF(AND(B25>=1.1,B25<=1.25,B21>=150,B21<=300),"RATION EQUILIBRE","CONTRÔLE NECESSAIRE") -> CONTRÔLE NECESSAIRE
A26: MSI cible f(UFL tot) | B26: =B34/0.9 -> 20.076917
A27: CI théorique f(poids vif) | B27: =0.028*B6 -> 19.88
A28: Écart MSI cible/réelle | B28: =IFERROR(MIN(B26,B27)-B16,"") -> 5.17
A29: Production lait théorique | B29: =B11*B10*(B12^0.18*EXP(-0.0032*B12))/((60^0.18)*EXP(-0.0032*60))*(1-ABS(B5-3)*0.03)*IF(B18<5,1,1-0.015*(B18-4)) -> 26.588009
A30: UFL entretien | B30: =0.041*B6^0.75 -> 5.6393314
A31: UFL production | B31: =B29*(0.44+0.0055*(B14-40)+0.0033*(B15-31)) -> 12.429894
A32: UFL gestation | B32: =IF(B18<7,0,IF(B18=7,0.3,IF(B18=8,0.6,0.9))) -> 0
A33: UFL croissance | B33: =IF(OR(B9="1",B9=1),0.4,0) -> 0
A34: UFL total besoin | B34: =B30+B31+B32+B33 -> 18.069226
A35: PDI entretien | B35: =3*(B6^0.75) -> 412.63401
A36: PDI production | B36: =1.92*B8*B29 -> 1745.875
A37: PDI gestation | B37: =IF(B18<7,0,IF(B18=7,60,IF(B18=8,120,180))) -> 0
A38: PDI croissance | B38: =IF(OR(B9="1",B9=1),150,0) -> 0
A39: PDI total besoin | B39: =SUM(B35:B38) -> 2158.509
A40: NDF min kg | B40: =IF(B29>35,0.3*B26,IF(B29>25,0.32*B26,0.35*B26)) -> 6.4246136
A41: ADF min kg | B41: =IF(B13>35,0.18*B26,IF(B13>25,0.2*B26,0.22*B26)) -> 4.0153835
A42: Amidon max kg | B42: =B40/1.3 -> 4.9420104
...

Sheet Bibliothèque MP INRA
A1: Catégorie | B1: Sous-catégorie | C1: Matière première | D1: MS (%) | E1: UFL/kg MS | F1: UFV/kg MS | G1: PDIN | H1: PDIE | I1: MAT (%) | J1: Amidon (%) | K1: Sucres (%) | L1: NDF (%) | M1: ADF (%) | N1: MG (%) | O1: Ca (%) | P1: P (%) | Q1: K (%) | R1: Na (%) | S1: Coût €/t | T1: Remarques nutritionnelles
A2: Fourrage | B2: Ensilage | C2: Ensilage maïs | D2: 33 | E2: 0.92 | F2: 0.88 | G2: 62 | H2: 90 | I2: 8 | J2: 32 | K2: 3 | L2: 42 | M2: 24 | N2: 3 | O2: 0.25 | P2: 0.22 | Q2: 1.1 | R2: 0.02 | T2: Énergie amidon
A3: Fourrage | B3: Ensilage | C3: Ensilage herbe | D3: 35 | E3: 0.85 | F3: 0.8 | G3: 85 | H3: 78 | I3: 15 | J3: 4 | K3: 6 | L3: 48 | M3: 30 | N3: 4 | O3: 0.65 | P3: 0.3 | Q3: 2.2 | R3: 0.04 | T3: Fibre + protéine
A4: Fourrage | B4: Foin | C4: Foin prairie | D4: 86 | E4: 0.7 | F4: 0.65 | G4: 70 | H4: 72 | I4: 12 | J4: 2 | K4: 8 | L4: 58 | M4: 35 | N4: 2 | O4: 0.55 | P4: 0.25 | Q4: 1.8 | R4: 0.03 | T4: Base fibre
A5: Fourrage | B5: Foin | C5: Luzerne foin | D5: 88 | E5: 0.78 | F5: 0.72 | G5: 120 | H5: 95 | I5: 18 | J5: 3 | K5: 7 | L5: 42 | M5: 30 | N5: 2.5 | O5: 1.3 | P5: 0.25 | Q5: 2 | R5: 0.03 | T5: Calcium + PDI
A6: Fourrage | B6: Paille | C6: Paille blé | D6: 90 | E6: 0.38 | F6: 0.32 | G6: 22 | H6: 28 | I6: 4 | J6: 0 | K6: 1 | L6: 75 | M6: 50 | N6: 1.3 | O6: 0.18 | P6: 0.1 | Q6: 1.2 | R6: 0.02 | T6: Fibre physique
A7: Fourrage | B7: Paille | C7: Paille riz | D7: 90 | E7: 0.35 | F7: 0.3 | G7: 20 | H7: 25 | I7: 4 | J7: 0 | K7: 1 | L7: 72 | M7: 48 | N7: 1.2 | O7: 0.2 | P7: 0.08 | Q7: 1.1 | R7: 0.02 | T7: Très fibreux
A8: Fourrage | B8: Pâture | C8: Ray-grass pâturé | D8: 18 | E8: 0.98 | F8: 0.92 | G8: 145 | H8: 110 | I8: 22 | J8: 3 | K8: 12 | L8: 38 | M8: 24 | N8: 4 | O8: 0.8 | P8: 0.4 | Q8: 3 | R8: 0.05 | T8: Très digestible
A9: Fourrage | B9: Pâture | C9: Trèfle blanc | D9: 20 | E9: 0.95 | F9: 0.9 | G9: 135 | H9: 110 | I9: 22 | J9: 2 | K9: 10 | L9: 35 | M9: 24 | N9: 4 | O9: 1.2 | P9: 0.35 | Q9: 2.8 | R9: 0.04 | T9: Protéique
A10: Fourrage | B10: Pâture | C10: Trèfle violet | D10: 18 | E10: 0.9 | F10: 0.84 | G10: 125 | H10: 100 | I10: 20 | J10: 2 | K10: 9 | L10: 40 | M10: 26 | N10: 3.5 | O10: 1.1 | P10: 0.3 | Q10: 2.6 | R10: 0.04 | T10: Digestible
A11: Céréale | B11: Grain | C11: Maïs grain | D11: 87 | E11: 1.18 | F11: 1.14 | G11: 65 | H11: 95 | I11: 9 | J11: 70 | K11: 2 | L11: 12 | M11: 4 | N11: 4 | O11: 0.03 | P11: 0.28 | Q11: 0.4 | R11: 0.02 | T11: Très énergétique
A12: Céréale | B12: Grain | C12: Blé | D12: 88 | E12: 1.2 | F12: 1.15 | G12: 85 | H12: 110 | I12: 13 | J12: 62 | K12: 3 | L12: 14 | M12: 4 | N12: 2 | O12: 0.05 | P12: 0.35 | Q12: 0.5 | R12: 0.02 | T12: Très fermentescible
A13: Céréale | B13: Grain | C13: Orge | D13: 87 | E13: 1.1 | F13: 1.05 | G13: 90 | H13: 105 | I13: 11 | J13: 58 | K13: 3 | L13: 18 | M13: 6 | N13: 2.5 | O13: 0.06 | P13: 0.38 | Q13: 0.5 | R13: 0.02 | T13: Équilibré
... A53: Additif | B53: Minéral/Fonctionnel | C53: Urée feed | D53: 100 | E53: 0 | F53: 0 | G53: 0 | H53: 0 | I53: 0 | J53: 0 | K53: 0 | L53: 0 | M53: 0 | N53: 0 | O53: 0 | P53: 0 | Q53: 0 | R53: 0 | T53: Fonctionnel
A54: Additif | B54: Minéral/Fonctionnel | C54: 5/25/5 | D54: 100 | E54: 0 | F54: 0 | G54: 0 | H54: 0 | I54: 0 | J54: 0 | K54: 0 | L54: 0 | M54: 0 | N54: 0 | O54: 25 | P54: 5 | Q54: 0 | R54: 0
A55: Divers | B55: Alternatif | C55: Canne fourragère | D55: 35 | E55: 0.45 | F55: 0.4 | G55: 40 | H55: 45 | I55: 5 | J55: 2 | K55: 5 | L55: 30 | M55: 18 | N55: 2 | O55: 0.3 | P55: 0.2 | Q55: 1 | R55: 0.03 | T55: Alternative régionale
A56: Divers | B56: Alternatif | C56: Foin de brousse | D56: 80 | E56: 0.53 | F56: 0.4 | G56: 45 | H56: 49 | I56: 6 | J56: 2 | K56: 5 | L56: 31 | M56: 19 | N56: 2 | O56: 0.3 | P56: 0.2 | Q56: 1 | R56: 0.03 | T56: Alternative régionale
A57: Divers | B57: Alternatif | C57: Bagasse canne | D57: 35 | E57: 0.61 | F57: 0.4 | G57: 50 | H57: 53 | I57: 7 | J57: 2 | K57: 5 | L57: 32 | M57: 20 | N57: 2 | O57: 0.3 | P57: 0.2 | Q57: 1 | R57: 0.03 | T57: Alternative régionale
A58: Divers | B58: Alternatif | C58: Fanes arachide | D58: 35 | E58: 0.69 | F58: 0.4 | G58: 55 | H58: 57 | I58: 8 | J58: 2 | K58: 5 | L58: 33 | M58: 21 | N58: 2 | O58: 0.3 | P58: 0.2 | Q58: 1 | R58: 0.03 | T58: Alternative régionale
A59: Divers | B59: Alternatif | C59: Fanes pois | D59: 35 | E59: 0.77 | F59: 0.4 | G59: 60 | H59: 61 | I59: 9 | J59: 2 | K59: 5 | L59: 34 | M59: 22 | N59: 2 | O59: 0.3 | P59: 0.2 | Q59: 1 | R59: 0.03 | T59: Alternative régionale
A60: Divers | B60: Alternatif | C60: Fanes patate douce | D60: 35 | E60: 0.85 | F60: 0.4 | G60: 65 | H60: 65 | I60: 10 | J60: 2 | K60: 5 | L60: 35 | M60: 23 | N60: 2 | O60: 0.3 | P60: 0.2 | Q60: 1 | R60: 0.03 | T60: Alternative régionale
A61: Divers | B61: Alternatif | C61: Maïs humide | D61: 35 | E61: 0.93 | F61: 0.4 | G61: 70 | H61: 69 | I61: 11 | J61: 2 | K61: 5 | L61: 36 | M61: 24 | N61: 2 | O61: 0.3 | P61: 0.2 | Q61: 1 | R61: 0.03 | T61: Alternative régionale
A62: Divers | B62: Alternatif | C62: Ensilage sorgho | D62: 35 | E62: 1.01 | F62: 0.4 | G62: 75 | H62: 73 | I62: 12 | J62: 2 | K62: 5 | L62: 37 | M62: 25 | N62: 2 | O62: 0.3 | P62: 0.2 | Q62: 1 | R62: 0.03 | T62: Alternative régionale
A63: Divers | B63: Alternatif | C63: Enrubannage luzerne | D63: 35 | E63: 0.45 | F63: 0.4 | G63: 80 | H63: 77 | I63: 13 | J63: 2 | K63: 5 | L63: 38 | M63: 26 | N63: 2 | O63: 0.3 | P63: 0.2 | Q63: 1 | R63: 0.03 | T63: Alternative régionale
A64: Divers | B64: Alternatif | C64: Foin dactyle | D64: 80 | E64: 0.53 | F64: 0.4 | G64: 85 | H64: 81 | I64: 14 | J64: 2 | K64: 5 | L64: 39 | M64: 27 | N64: 2 | O64: 0.3 | P64: 0.2 | Q64: 1 | R64: 0.03 | T64: Alternative régionale
A65: Divers | B65: Alternatif | C65: Foin fléole | D65: 80 | E65: 0.61 | F65: 0.4 | G65: 90 | H65: 85 | I65: 15 | J65: 2 | K65: 5 | L65: 40 | M65: 28 | N65: 2 | O65: 0.3 | P65: 0.2 | Q65: 1 | R65: 0.03 | T65: Alternative régionale
A66: Divers | B66: Alternatif | C66: Paille orge | D66: 80 | E66: 0.69 | F66: 0.4 | G66: 95 | H66: 89 | I66: 16 | J66: 2 | K66: 5 | L66: 41 | M66: 29 | N66: 2 | O66: 0.3 | P66: 0.2 | Q66: 1 | R66: 0.03 | T66: Alternative régionale
... A74: Divers | B74: Alternatif | C74: Vinasse | D74: 35 | E74: 0.69 | F74: 0.4 | G74: 135 | H74: 121 | I74: 24 | J74: 2 | K74: 5 | L74: 49 | M74: 37 | N74: 2 | O74: 0.3 | P74: 0.2 | Q74: 1 | R74: 0.03 | T74: Alternative régionale

Sheet Ration Formulation
A1: RATION FORMULATION – LOGIQUE BRUT + APPORTÉ
A3: Matière première | B3: Incorporation kg brut | C3: MS brut | D3: MS apporté | E3: UFL brut | F3: UFL apporté | G3: MAT brut | H3: MAT apporté | I3: PDIN brut | J3: PDIN apporté | K3: PDIE brut | L3: PDIE apporté | M3: Amidon brut | N3: Amidon apporté | O3: Sucres brut | P3: Sucres apporté | Q3: NDF brut | R3: NDF apporté | S3: ADF brut | T3: ADF apporté | U3: MG brut | V3: MG apporté | W3: Ca brut | X3: Ca apporté | Y3: P brut | Z3: P apporté | AA3: Na brut | AB3: Na apporté | AC3: K brut | AD3: K apporté | AE3: Coût brut | AF3: Coût apporté
A4: Ensilage maïs | B4: 25 | C4: =IFERROR(INDEX('Bibliothèque MP INRA'!$D:$D,MATCH($A4,'Bibliothèque MP INRA'!$C:$C,0)),"") -> 33 | D4: =IFERROR($B4*C4/100,"") -> 8.25 | E4: =IFERROR(INDEX('Bibliothèque MP INRA'!$E:$E,MATCH($A4,'Bibliothèque MP INRA'!$C:$C,0)),"") -> 0.92 | F4: =IFERROR(D4*E4,"") -> 7.59 | G4: =IFERROR(INDEX('Bibliothèque MP INRA'!$I:$I,MATCH($A4,'Bibliothèque MP INRA'!$C:$C,0)),"") -> 8 | H4: =IFERROR(D4*G4/100,"") -> 0.66 | I4: =IFERROR(INDEX('Bibliothèque MP INRA'!$G:$G,MATCH($A4,'Bibliothèque MP INRA'!$C:$C,0)),"") -> 62 | J4: =IFERROR(D4*I4,"") -> 511.5 | K4: =IFERROR(INDEX('Bibliothèque MP INRA'!$H:$H,MATCH($A4,'Bibliothèque MP INRA'!$C:$C,0)),"") -> 90 | L4: =IFERROR(D4*K4,"") -> 742.5 | M4: =IFERROR(INDEX('Bibliothèque MP INRA'!$J:$J,MATCH($A4,'Bibliothèque MP INRA'!$C:$C,0)),"") -> 32 | N4: =IFERROR(D4*M4/100,"") -> 2.64 | O4: =IFERROR(INDEX('Bibliothèque MP INRA'!$K:$K,MATCH($A4,'Bibliothèque MP INRA'!$C:$C,0)),"") -> 3 | P4: =IFERROR(D4*O4/100,"") -> 0.2475 | Q4: =IFERROR(INDEX('Bibliothèque MP INRA'!$L:$L,MATCH($A4,'Bibliothèque MP INRA'!$C:$C,0)),"") -> 42 | R4: =IFERROR(D4*Q4/100,"") -> 3.465 | S4: =IFERROR(INDEX('Bibliothèque MP INRA'!$M:$M,MATCH($A4,'Bibliothèque MP INRA'!$C:$C,0)),"") -> 24 | T4: =IFERROR(D4*S4/100,"") -> 1.98 | U4: =IFERROR(INDEX('Bibliothèque MP INRA'!$N:$N,MATCH($A4,'Bibliothèque MP INRA'!$C:$C,0)),"") -> 3 | V4: =IFERROR(D4*U4/100,"") -> 0.2475 | W4: =IFERROR(INDEX('Bibliothèque MP INRA'!$O:$O,MATCH($A4,'Bibliothèque MP INRA'!$C:$C,0)),"") -> 0.25 | X4: =IFERROR(D4*W4,"") -> 2.0625 | Y4: =IFERROR(INDEX('Bibliothèque MP INRA'!$P:$P,MATCH($A4,'Bibliothèque MP INRA'!$C:$C,0)),"") -> 0.22 | Z4: =IFERROR(D4*Y4/100,"") -> 0.01815 | AA4: =IFERROR(INDEX('Bibliothèque MP INRA'!$R:$R,MATCH($A4,'Bibliothèque MP INRA'!$C:$C,0)),"") -> 0.02 | AB4: =IFERROR(D4*AA4/100,"") -> 0.00165 | AC4: =IFERROR(INDEX('Bibliothèque MP INRA'!$Q:$Q,MATCH($A4,'Bibliothèque MP INRA'!$C:$C,0)),"") -> 1.1 | AD4: =IFERROR(D4*AC4/100,"") -> 0.09075 | AE4: =IFERROR(INDEX('Bibliothèque MP INRA'!$S:$S,MATCH($A4,'Bibliothèque MP INRA'!$C:$C,0)),"") -> 0 | AF4: =IFERROR($B4*AE4/1000,"") -> 0
A5: Paille blé | B5: 1 | C5: =IFERROR(INDEX('Bibliothèque MP INRA'!$D:$D,MATCH($A5,'Bibliothèque MP INRA'!$C:$C,0)),"") -> 90 | D5: =IFERROR($B5*C5/100,"") -> 0.9 | E5: =IFERROR(INDEX('Bibliothèque MP INRA'!$E:$E,MATCH($A5,'Bibliothèque MP INRA'!$C:$C,0)),"") -> 0.38 | F5: =IFERROR(D5*E5,"") -> 0.342 | G5: =IFERROR(INDEX('Bibliothèque MP INRA'!$I:$I,MATCH($A5,'Bibliothèque MP INRA'!$C:$C,0)),"") -> 4 | H5: =IFERROR(D5*G5/100,"") -> 0.036 | I5: =IFERROR(INDEX('Bibliothèque MP INRA'!$G:$G,MATCH($A5,'Bibliothèque MP INRA'!$C:$C,0)),"") -> 22 | J5: =IFERROR(D5*I5,"") -> 19.8 | K5: =IFERROR(INDEX('Bibliothèque MP INRA'!$H:$H,MATCH($A5,'Bibliothèque MP INRA'!$C:$C,0)),"") -> 28 | L5: =IFERROR(D5*K5,"") -> 25.2 | M5: =IFERROR(INDEX('Bibliothèque MP INRA'!$J:$J,MATCH($A5,'Bibliothèque MP INRA'!$C:$C,0)),"") -> 0 | N5: =IFERROR(D5*M5/100,"") -> 0 | O5: =IFERROR(INDEX('Bibliothèque MP INRA'!$K:$K,MATCH($A5,'Bibliothèque MP INRA'!$C:$C,0)),"") -> 1 | P5: =IFERROR(D5*O5/100,"") -> 0.009 | Q5: =IFERROR(INDEX('Bibliothèque MP INRA'!$L:$L,MATCH($A5,'Bibliothèque MP INRA'!$C:$C,0)),"") -> 75 | R5: =IFERROR(D5*Q5/100,"") -> 0.675 | S5: =IFERROR(INDEX('Bibliothèque MP INRA'!$M:$M,MATCH($A5,'Bibliothèque MP INRA'!$C:$C,0)),"") -> 50 | T5: =IFERROR(D5*S5/100,"") -> 0.45 | U5: =IFERROR(INDEX('Bibliothèque MP INRA'!$N:$N,MATCH($A5,'Bibliothèque MP INRA'!$C:$C,0)),"") -> 1.3 | V5: =IFERROR(D5*U5/100,"") -> 0.0117 | W5: =IFERROR(INDEX('Bibliothèque MP INRA'!$O:$O,MATCH($A5,'Bibliothèque MP INRA'!$C:$C,0)),"") -> 0.18 | X5: =IFERROR(D5*W5/100,"") -> 0.00162 | Y5: =IFERROR(INDEX('Bibliothèque MP INRA'!$P:$P,MATCH($A5,'Bibliothèque MP INRA'!$C:$C,0)),"") -> 0.1 | Z5: =IFERROR(D5*Y5/100,"") -> 0.0009 | AA5: =IFERROR(INDEX('Bibliothèque MP INRA'!$R:$R,MATCH($A5,'Bibliothèque MP INRA'!$C:$C,0)),"") -> 0.02 | AB5: =IFERROR(D5*AA5/100,"") -> 0.00018 | AC5: =IFERROR(INDEX('Bibliothèque MP INRA'!$Q:$Q,MATCH($A5,'Bibliothèque MP INRA'!$C:$C,0)),"") -> 1.2 | AD5: =IFERROR(D5*AC5/100,"") -> 0.0108 | AE5: =IFERROR(INDEX('Bibliothèque MP INRA'!$S:$S,MATCH($A5,'Bibliothèque MP INRA'!$C:$C,0)),"") -> 0 | AF5: =IFERROR($B5*AE5/1000,"") -> 0
A6: Maïs grain | B6: 2 | C6: =IFERROR(INDEX('Bibliothèque MP INRA'!$D:$D,MATCH($A6,'Bibliothèque MP INRA'!$C:$C,0)),"") -> 87 | D6: =IFERROR($B6*C6/100,"") -> 1.74 | E6: =IFERROR(INDEX('Bibliothèque MP INRA'!$E:$E,MATCH($A6,'Bibliothèque MP INRA'!$C:$C,0)),"") -> 1.18 | F6: =IFERROR(D6*E6,"") -> 2.0532 | G6: =IFERROR(INDEX('Bibliothèque MP INRA'!$I:$I,MATCH($A6,'Bibliothèque MP INRA'!$C:$C,0)),"") -> 9 | H6: =IFERROR(D6*G6/100,"") -> 0.1566 | I6: =IFERROR(INDEX('Bibliothèque MP INRA'!$G:$G,MATCH($A6,'Bibliothèque MP INRA'!$C:$C,0)),"") -> 65 | J6: =IFERROR(D6*I6,"") -> 113.1 | K6: =IFERROR(INDEX('Bibliothèque MP INRA'!$H:$H,MATCH($A6,'Bibliothèque MP INRA'!$C:$C,0)),"") -> 95 | L6: =IFERROR(D6*K6,"") -> 165.3 | M6: =IFERROR(INDEX('Bibliothèque MP INRA'!$J:$J,MATCH($A6,'Bibliothèque MP INRA'!$C:$C,0)),"") -> 70 | N6: =IFERROR(D6*M6/100,"") -> 1.218 | O6: =IFERROR(INDEX('Bibliothèque MP INRA'!$K:$K,MATCH($A6,'Bibliothèque MP INRA'!$C:$C,0)),"") -> 2 | P6: =IFERROR(D6*O6/100,"") -> 0.0348 | Q6: =IFERROR(INDEX('Bibliothèque MP INRA'!$L:$L,MATCH($A6,'Bibliothèque MP INRA'!$C:$C,0)),"") -> 12 | R6: =IFERROR(D6*Q6/100,"") -> 0.2088 | S6: =IFERROR(INDEX('Bibliothèque MP INRA'!$M:$M,MATCH($A6,'Bibliothèque MP INRA'!$C:$C,0)),"") -> 4 | T6: =IFERROR(D6*S6/100,"") -> 0.0696 | U6: =IFERROR(INDEX('Bibliothèque MP INRA'!$N:$N,MATCH($A6,'Bibliothèque MP INRA'!$C:$C,0)),"") -> 4 | V6: =IFERROR(D6*U6/100,"") -> 0.0696 | W6: =IFERROR(INDEX('Bibliothèque MP INRA'!$O:$O,MATCH($A6,'Bibliothèque MP INRA'!$C:$C,0)),"") -> 0.03 | X6: =IFERROR(D6*W6,"") -> 0.0522 | Y6: =IFERROR(INDEX('Bibliothèque MP INRA'!$P:$P,MATCH($A6,'Bibliothèque MP INRA'!$C:$C,0)),"") -> 0.28 | Z6: =IFERROR(D6*Y6/100,"") -> 0.004872 | AA6: =IFERROR(INDEX('Bibliothèque MP INRA'!$R:$R,MATCH($A6,'Bibliothèque MP INRA'!$C:$C,0)),"") -> 0.02 | AB6: =IFERROR(D6*AA6/100,"") -> 0.000348 | AC6: =IFERROR(INDEX('Bibliothèque MP INRA'!$Q:$Q,MATCH($A6,'Bibliothèque MP INRA'!$C:$C,0)),"") -> 0.4 | AD6: =IFERROR(D6*AC6/100,"") -> 0.00696 | AE6: =IFERROR(INDEX('Bibliothèque MP INRA'!$S:$S,MATCH($A6,'Bibliothèque MP INRA'!$C:$C,0)),"") -> 0 | AF6: =IFERROR($B6*AE6/1000,"") -> 0
A7: Orge | B7: 1 | C7: =IFERROR(INDEX('Bibliothèque MP INRA'!$D:$D,MATCH($A7,'Bibliothèque MP INRA'!$C:$C,0)),"") -> 87 | D7: =IFERROR($B7*C7/100,"") -> 0.87 | E7: =IFERROR(INDEX('Bibliothèque MP INRA'!$E:$E,MATCH($A7,'Bibliothèque MP INRA'!$C:$C,0)),"") -> 1.1 | F7: =IFERROR(D7*E7,"") -> 0.957 | G7: =IFERROR(INDEX('Bibliothèque MP INRA'!$I:$I,MATCH($A7,'Bibliothèque MP INRA'!$C:$C,0)),"") -> 11 | H7: =IFERROR(D7*G7/100,"") -> 0.0957 | I7: =IFERROR(INDEX('Bibliothèque MP INRA'!$G:$G,MATCH($A7,'Bibliothèque MP INRA'!$C:$C,0)),"") -> 90 | J7: =IFERROR(D7*I7,"") -> 78.3 | K7: =IFERROR(INDEX('Bibliothèque MP INRA'!$H:$H,MATCH($A7,'Bibliothèque MP INRA'!$C:$C,0)),"") -> 105 | L7: =IFERROR(D7*K7,"") -> 91.35 | M7: =IFERROR(INDEX('Bibliothèque MP INRA'!$J:$J,MATCH($A7,'Bibliothèque MP INRA'!$C:$C,0)),"") -> 58 | N7: =IFERROR(D7*M7/100,"") -> 0.5046 | O7: =IFERROR(INDEX('Bibliothèque MP INRA'!$K:$K,MATCH($A7,'Bibliothèque MP INRA'!$C:$C,0)),"") -> 3 | P7: =IFERROR(D7*O7/100,"") -> 0.0261 | Q7: =IFERROR(INDEX('Bibliothèque MP INRA'!$L:$L,MATCH($A7,'Bibliothèque MP INRA'!$C:$C,0)),"") -> 18 | R7: =IFERROR(D7*Q7/100,"") -> 0.1566 | S7: =IFERROR(INDEX('Bibliothèque MP INRA'!$M:$M,MATCH($A7,'Bibliothèque MP INRA'!$C:$C,0)),"") -> 6 | T7: =IFERROR(D7*S7/100,"") -> 0.0522 | U7: =IFERROR(INDEX('Bibliothèque MP INRA'!$N:$N,MATCH($A7,'Bibliothèque MP INRA'!$C:$C,0)),"") -> 2.5 | V7: =IFERROR(D7*U7/100,"") -> 0.02175 | W7: =IFERROR(INDEX('Bibliothèque MP INRA'!$O:$O,MATCH($A7,'Bibliothèque MP INRA'!$C:$C,0)),"") -> 0.06 | X7: =IFERROR(D7*W7,"") -> 0.0522 | Y7: =IFERROR(INDEX('Bibliothèque MP INRA'!$P:$P,MATCH($A7,'Bibliothèque MP INRA'!$C:$C,0)),"") -> 0.38 | Z7: =IFERROR(D7*Y7/100,"") -> 0.003306 | AA7: =IFERROR(INDEX('Bibliothèque MP INRA'!$R:$R,MATCH($A7,'Bibliothèque MP INRA'!$C:$C,0)),"") -> 0.02 | AB7: =IFERROR(D7*AA7/100,"") -> 0.000174 | AC7: =IFERROR(INDEX('Bibliothèque MP INRA'!$Q:$Q,MATCH($A7,'Bibliothèque MP INRA'!$C:$C,0)),"") -> 0.5 | AD7: =IFERROR(D7*AC7/100,"") -> 0.00435 | AE7: =IFERROR(INDEX('Bibliothèque MP INRA'!$S:$S,MATCH($A7,'Bibliothèque MP INRA'!$C:$C,0)),"") -> 0 | AF7: =IFERROR($B7*AE7/1000,"") -> 0
A8: Blé | C8: =IFERROR(INDEX('Bibliothèque MP INRA'!$D:$D,MATCH($A8,'Bibliothèque MP INRA'!$C:$C,0)),"") -> 88 | D8: =IFERROR($B8*C8/100,"") -> 0 | E8: =IFERROR(INDEX('Bibliothèque MP INRA'!$E:$E,MATCH($A8,'Bibliothèque MP INRA'!$C:$C,0)),"") -> 1.2 | F8: =IFERROR(D8*E8,"") -> 0 | G8: =IFERROR(INDEX('Bibliothèque MP INRA'!$I:$I,MATCH($A8,'Bibliothèque MP INRA'!$C:$C,0)),"") -> 13 | H8: =IFERROR(D8*G8/100,"") -> 0 | I8: =IFERROR(INDEX('Bibliothèque MP INRA'!$G:$G,MATCH($A8,'Bibliothèque MP INRA'!$C:$C,0)),"") -> 85 | J8: =IFERROR(D8*I8,"") -> 0 | K8: =IFERROR(INDEX('Bibliothèque MP INRA'!$H:$H,MATCH($A8,'Bibliothèque MP INRA'!$C:$C,0)),"") -> 110 | L8: =IFERROR(D8*K8,"") -> 0 | M8: =IFERROR(INDEX('Bibliothèque MP INRA'!$J:$J,MATCH($A8,'Bibliothèque MP INRA'!$C:$C,0)),"") -> 62 | N8: =IFERROR(D8*M8/100,"") -> 0 | O8: =IFERROR(INDEX('Bibliothèque MP INRA'!$K:$K,MATCH($A8,'Bibliothèque MP INRA'!$C:$C,0)),"") -> 3 | P8: =IFERROR(D8*O8/100,"") -> 0 | Q8: =IFERROR(INDEX('Bibliothèque MP INRA'!$L:$L,MATCH($A8,'Bibliothèque MP INRA'!$C:$C,0)),"") -> 14 | R8: =IFERROR(D8*Q8/100,"") -> 0 | S8: =IFERROR(INDEX('Bibliothèque MP INRA'!$M:$M,MATCH($A8,'Bibliothèque MP INRA'!$C:$C,0)),"") -> 4 | T8: =IFERROR(D8*S8/100,"") -> 0 | U8: =IFERROR(INDEX('Bibliothèque MP INRA'!$N:$N,MATCH($A8,'Bibliothèque MP INRA'!$C:$C,0)),"") -> 2 | V8: =IFERROR(D8*U8/100,"") -> 0 | W8: =IFERROR(INDEX('Bibliothèque MP INRA'!$O:$O,MATCH($A8,'Bibliothèque MP INRA'!$C:$C,0)),"") -> 0.05 | X8: =IFERROR(D8*W8,"") -> 0 | Y8: =IFERROR(INDEX('Bibliothèque MP INRA'!$P:$P,MATCH($A8,'Bibliothèque MP INRA'!$C:$C,0)),"") -> 0.35 | Z8: =IFERROR(D8*Y8/100,"") -> 0 | AA8: =IFERROR(INDEX('Bibliothèque MP INRA'!$R:$R,MATCH($A8,'Bibliothèque MP INRA'!$C:$C,0)),"") -> 0.02 | AB8: =IFERROR(D8*AA8/100,"") -> 0 | AC8: =IFERROR(INDEX('Bibliothèque MP INRA'!$Q:$Q,MATCH($A8,'Bibliothèque MP INRA'!$C:$C,0)),"") -> 0.5 | AD8: =IFERROR(D8*AC8/100,"") -> 0 | AE8: =IFERROR(INDEX('Bibliothèque MP INRA'!$S:$S,MATCH($A8,'Bibliothèque MP INRA'!$C:$C,0)),"") -> 0 | AF8: =IFERROR($B8*AE8/1000,"") -> 0
A9: Tourteau Soja | B9: 1 | C9: =IFERROR(INDEX('Bibliothèque MP INRA'!$D:$D,MATCH($A9,'Bibliothèque MP INRA'!$C:$C,0)),"") -> 89 | D9: =IFERROR($B9*C9/100,"") -> 0.89 | E9: =IFERROR(INDEX('Bibliothèque MP INRA'!$E:$E,MATCH($A9,'Bibliothèque MP INRA'!$C:$C,0)),"") -> 1 | F9: =IFERROR(D9*E9,"") -> 0.89 | G9: =IFERROR(INDEX('Bibliothèque MP INRA'!$I:$I,MATCH($A9,'Bibliothèque MP INRA'!$C:$C,0)),"") -> 25 | H9: =IFERROR(D9*G9/100,"") -> 0.2225 | I9: =IFERROR(INDEX('Bibliothèque MP INRA'!$G:$G,MATCH($A9,'Bibliothèque MP INRA'!$C:$C,0)),"") -> 120 | J9: =IFERROR(D9*I9,"") -> 106.8 | K9: =IFERROR(INDEX('Bibliothèque MP INRA'!$H:$H,MATCH($A9,'Bibliothèque MP INRA'!$C:$C,0)),"") -> 105 | L9: =IFERROR(D9*K9,"") -> 93.45 | M9: =IFERROR(INDEX('Bibliothèque MP INRA'!$J:$J,MATCH($A9,'Bibliothèque MP INRA'!$C:$C,0)),"") -> 2 | N9: =IFERROR(D9*M9/100,"") -> 0.0178 | O9: =IFERROR(INDEX('Bibliothèque MP INRA'!$K:$K,MATCH($A9,'Bibliothèque MP INRA'!$C:$C,0)),"") -> 4 | P9: =IFERROR(D9*O9/100,"") -> 0.0356 | Q9: =IFERROR(INDEX('Bibliothèque MP INRA'!$L:$L,MATCH($A9,'Bibliothèque MP INRA'!$C:$C,0)),"") -> 18 | R9: =IFERROR(D9*Q9/100,"") -> 0.1602 | S9: =IFERROR(INDEX('Bibliothèque MP INRA'!$M:$M,MATCH($A9,'Bibliothèque MP INRA'!$C:$C,0)),"") -> 12 | T9: =IFERROR(D9*S9/100,"") -> 0.1068 | U9: =IFERROR(INDEX('Bibliothèque MP INRA'!$N:$N,MATCH($A9,'Bibliothèque MP INRA'!$C:$C,0)),"") -> 2 | V9: =IFERROR(D9*U9/100,"") -> 0.0178 | W9: =IFERROR(INDEX('Bibliothèque MP INRA'!$O:$O,MATCH($A9,'Bibliothèque MP INRA'!$C:$C,0)),"") -> 0.3 | X9: =IFERROR(D9*W9,"") -> 0.267 | Y9: =IFERROR(INDEX('Bibliothèque MP INRA'!$P:$P,MATCH($A9,'Bibliothèque MP INRA'!$C:$C,0)),"") -> 0.4 | Z9: =IFERROR(D9*Y9/100,"") -> 0.00356 | AA9: =IFERROR(INDEX('Bibliothèque MP INRA'!$R:$R,MATCH($A9,'Bibliothèque MP INRA'!$C:$C,0)),"") -> 0.03 | AB9: =IFERROR(D9*AA9/100,"") -> 0.000267 | AC9: =IFERROR(INDEX('Bibliothèque MP INRA'!$Q:$Q,MATCH($A9,'Bibliothèque MP INRA'!$C:$C,0)),"") -> 1.2 | AD9: =IFERROR(D9*AC9/100,"") -> 0.01068 | AE9: =IFERROR(INDEX('Bibliothèque MP INRA'!$S:$S,MATCH($A9,'Bibliothèque MP INRA'!$C:$C,0)),"") -> 0 | AF9: =IFERROR($B9*AE9/1000,"") -> 0
A10: Tourteau Colza | B10: 2 | C10: =IFERROR(INDEX('Bibliothèque MP INRA'!$D:$D,MATCH($A10,'Bibliothèque MP INRA'!$C:$C,0)),"") -> 89 | D10: =IFERROR($B10*C10/100,"") -> 1.78 | E10: =IFERROR(INDEX('Bibliothèque MP INRA'!$E:$E,MATCH($A10,'Bibliothèque MP INRA'!$C:$C,0)),"") -> 1.03 | F10: =IFERROR(D10*E10,"") -> 1.8334 | G10: =IFERROR(INDEX('Bibliothèque MP INRA'!$I:$I,MATCH($A10,'Bibliothèque MP INRA'!$C:$C,0)),"") -> 27 | H10: =IFERROR(D10*G10/100,"") -> 0.4806 | I10: =IFERROR(INDEX('Bibliothèque MP INRA'!$G:$G,MATCH($A10,'Bibliothèque MP INRA'!$C:$C,0)),"") -> 128 | J10: =IFERROR(D10*I10,"") -> 227.84 | K10: =IFERROR(INDEX('Bibliothèque MP INRA'!$H:$H,MATCH($A10,'Bibliothèque MP INRA'!$C:$C,0)),"") -> 112 | L10: =IFERROR(D10*K10,"") -> 199.36 | M10: =IFERROR(INDEX('Bibliothèque MP INRA'!$J:$J,MATCH($A10,'Bibliothèque MP INRA'!$C:$C,0)),"") -> 3 | N10: =IFERROR(D10*M10/100,"") -> 0.0534 | O10: =IFERROR(INDEX('Bibliothèque MP INRA'!$K:$K,MATCH($A10,'Bibliothèque MP INRA'!$C:$C,0)),"") -> 4 | P10: =IFERROR(D10*O10/100,"") -> 0.0712 | Q10: =IFERROR(INDEX('Bibliothèque MP INRA'!$L:$L,MATCH($A10,'Bibliothèque MP INRA'!$C:$C,0)),"") -> 19 | R10: =IFERROR(D10*Q10/100,"") -> 0.3382 | S10: =IFERROR(INDEX('Bibliothèque MP INRA'!$M:$M,MATCH($A10,'Bibliothèque MP INRA'!$C:$C,0)),"") -> 13 | T10: =IFERROR(D10*S10/100,"") -> 0.2314 | U10: =IFERROR(INDEX('Bibliothèque MP INRA'!$N:$N,MATCH($A10,'Bibliothèque MP INRA'!$C:$C,0)),"") -> 3 | V10: =IFERROR(D10*U10/100,"") -> 0.0534 | W10: =IFERROR(INDEX('Bibliothèque MP INRA'!$O:$O,MATCH($A10,'Bibliothèque MP INRA'!$C:$C,0)),"") -> 0.3 | X10: =IFERROR(D10*W10,"") -> 0.534 | Y10: =IFERROR(INDEX('Bibliothèque MP INRA'!$P:$P,MATCH($A10,'Bibliothèque MP INRA'!$C:$C,0)),"") -> 0.4 | Z10: =IFERROR(D10*Y10/100,"") -> 0.00712 | AA10: =IFERROR(INDEX('Bibliothèque MP INRA'!$R:$R,MATCH($A10,'Bibliothèque MP INRA'!$C:$C,0)),"") -> 0.03 | AB10: =IFERROR(D10*AA10/100,"") -> 0.000534 | AC10: =IFERROR(INDEX('Bibliothèque MP INRA'!$Q:$Q,MATCH($A10,'Bibliothèque MP INRA'!$C:$C,0)),"") -> 1.2 | AD10: =IFERROR(D10*AC10/100,"") -> 0.02136 | AE10: =IFERROR(INDEX('Bibliothèque MP INRA'!$S:$S,MATCH($A10,'Bibliothèque MP INRA'!$C:$C,0)),"") -> 0 | AF10: =IFERROR($B10*AE10/1000,"") -> 0
A11: Sel | B11: 0.06 | C11: =IFERROR(INDEX('Bibliothèque MP INRA'!$D:$D,MATCH($A11,'Bibliothèque MP INRA'!$C:$C,0)),"") -> 100 | D11: =IFERROR($B11*C11/100,"") -> 0.06 | E11: =IFERROR(INDEX('Bibliothèque MP INRA'!$E:$E,MATCH($A11,'Bibliothèque MP INRA'!$C:$C,0)),"") -> 0 | F11: =IFERROR(D11*E11,"") -> 0 | G11: =IFERROR(INDEX('Bibliothèque MP INRA'!$I:$I,MATCH($A11,'Bibliothèque MP INRA'!$C:$C,0)),"") -> 0 | H11: =IFERROR(D11*G11/100,"") -> 0 | I11: =IFERROR(INDEX('Bibliothèque MP INRA'!$G:$G,MATCH($A11,'Bibliothèque MP INRA'!$C:$C,0)),"") -> 0 | J11: =IFERROR(D11*I11,"") -> 0 | K11: =IFERROR(INDEX('Bibliothèque MP INRA'!$H:$H,MATCH($A11,'Bibliothèque MP INRA'!$C:$C,0)),"") -> 0 | L11: =IFERROR(D11*K11,"") -> 0 | M11: =IFERROR(INDEX('Bibliothèque MP INRA'!$J:$J,MATCH($A11,'Bibliothèque MP INRA'!$C:$C,0)),"") -> 0 | N11: =IFERROR(D11*M11/100,"") -> 0 | O11: =IFERROR(INDEX('Bibliothèque MP INRA'!$K:$K,MATCH($A11,'Bibliothèque MP INRA'!$C:$C,0)),"") -> 0 | P11: =IFERROR(D11*O11/100,"") -> 0 | Q11: =IFERROR(INDEX('Bibliothèque MP INRA'!$L:$L,MATCH($A11,'Bibliothèque MP INRA'!$C:$C,0)),"") -> 0 | R11: =IFERROR(D11*Q11/100,"") -> 0 | S11: =IFERROR(INDEX('Bibliothèque MP INRA'!$M:$M,MATCH($A11,'Bibliothèque MP INRA'!$C:$C,0)),"") -> 0 | T11: =IFERROR(D11*S11/100,"") -> 0 | U11: =IFERROR(INDEX('Bibliothèque MP INRA'!$N:$N,MATCH($A11,'Bibliothèque MP INRA'!$C:$C,0)),"") -> 0 | V11: =IFERROR(D11*U11/100,"") -> 0 | W11: =IFERROR(INDEX('Bibliothèque MP INRA'!$O:$O,MATCH($A11,'Bibliothèque MP INRA'!$C:$C,0)),"") -> 0 | X11: =IFERROR(D11*W11,"") -> 0 | Y11: =IFERROR(INDEX('Bibliothèque MP INRA'!$P:$P,MATCH($A11,'Bibliothèque MP INRA'!$C:$C,0)),"") -> 0 | Z11: =IFERROR(D11*Y11/100,"") -> 0 | AA11: =IFERROR(INDEX('Bibliothèque MP INRA'!$R:$R,MATCH($A11,'Bibliothèque MP INRA'!$C:$C,0)),"") -> 0 | AB11: =IFERROR(D11*AA11/100,"") -> 0 | AC11: =IFERROR(INDEX('Bibliothèque MP INRA'!$Q:$Q,MATCH($A11,'Bibliothèque MP INRA'!$C:$C,0)),"") -> 0 | AD11: =IFERROR(D11*AC11/100,"") -> 0 | AE11: =IFERROR(INDEX('Bibliothèque MP INRA'!$S:$S,MATCH($A11,'Bibliothèque MP INRA'!$C:$C,0)),"") -> 0 | AF11: =IFERROR($B11*AE11/1000,"") -> 0
A12: Bicarbonate sodium | B12: 0.22 | C12: =IFERROR(INDEX('Bibliothèque MP INRA'!$D:$D,MATCH($A12,'Bibliothèque MP INRA'!$C:$C,0)),"") -> 100 | D12: =IFERROR($B12*C12/100,"") -> 0.22 | E12: =IFERROR(INDEX('Bibliothèque MP INRA'!$E:$E,MATCH($A12,'Bibliothèque MP INRA'!$C:$C,0)),"") -> 0 | F12: =IFERROR(D12*E12,"") -> 0 | G12: =IFERROR(INDEX('Bibliothèque MP INRA'!$I:$I,MATCH($A12,'Bibliothèque MP INRA'!$C:$C,0)),"") -> 0 | H12: =IFERROR(D12*G12/100,"") -> 0 | I12: =IFERROR(INDEX('Bibliothèque MP INRA'!$G:$G,MATCH($A12,'Bibliothèque MP INRA'!$C:$C,0)),"") -> 0 | J12: =IFERROR(D12*I12,"") -> 0 | K12: =IFERROR(INDEX('Bibliothèque MP INRA'!$H:$H,MATCH($A12,'Bibliothèque MP INRA'!$C:$C,0)),"") -> 0 | L12: =IFERROR(D12*K12,"") -> 0 | M12: =IFERROR(INDEX('Bibliothèque MP INRA'!$J:$J,MATCH($A12,'Bibliothèque MP INRA'!$C:$C,0)),"") -> 0 | N12: =IFERROR(D12*M12/100,"") -> 0 | O12: =IFERROR(INDEX('Bibliothèque MP INRA'!$K:$K,MATCH($A12,'Bibliothèque MP INRA'!$C:$C,0)),"") -> 0 | P12: =IFERROR(D12*O12/100,"") -> 0 | Q12: =IFERROR(INDEX('Bibliothèque MP INRA'!$L:$L,MATCH($A12,'Bibliothèque MP INRA'!$C:$C,0)),"") -> 0 | R12: =IFERROR(D12*Q12/100,"") -> 0 | S12: =IFERROR(INDEX('Bibliothèque MP INRA'!$M:$M,MATCH($A12,'Bibliothèque MP INRA'!$C:$C,0)),"") -> 0 | T12: =IFERROR(D12*S12/100,"") -> 0 | U12: =IFERROR(INDEX('Bibliothèque MP INRA'!$N:$N,MATCH($A12,'Bibliothèque MP INRA'!$C:$C,0)),"") -> 0 | V12: =IFERROR(D12*U12/100,"") -> 0 | W12: =IFERROR(INDEX('Bibliothèque MP INRA'!$O:$O,MATCH($A12,'Bibliothèque MP INRA'!$C:$C,0)),"") -> 0 | X12: =IFERROR(D12*W12,"") -> 0 | Y12: =IFERROR(INDEX('Bibliothèque MP INRA'!$P:$P,MATCH($A12,'Bibliothèque MP INRA'!$C:$C,0)),"") -> 0 | Z12: =IFERROR(D12*Y12/100,"") -> 0 | AA12: =IFERROR(INDEX('Bibliothèque MP INRA'!$R:$R,MATCH($A12,'Bibliothèque MP INRA'!$C:$C,0)),"") -> 0 | AB12: =IFERROR(D12*AA12/100,"") -> 0 | AC12: =IFERROR(INDEX('Bibliothèque MP INRA'!$Q:$Q,MATCH($A12,'Bibliothèque MP INRA'!$C:$C,0)),"") -> 0 | AD12: =IFERROR(D12*AC12/100,"") -> 0 | AE12: =IFERROR(INDEX('Bibliothèque MP INRA'!$S:$S,MATCH($A12,'Bibliothèque MP INRA'!$C:$C,0)),"") -> 0 | AF12: =IFERROR($B12*AE12/1000,"") -> 0
A13: 5/25/5 | C13: =IFERROR(INDEX('Bibliothèque MP INRA'!$D:$D,MATCH($A13,'Bibliothèque MP INRA'!$C:$C,0)),"") -> 100 | D13: =IFERROR($B13*C13/100,"") -> 0 | E13: =IFERROR(INDEX('Bibliothèque MP INRA'!$E:$E,MATCH($A13,'Bibliothèque MP INRA'!$C:$C,0)),"") -> 0 | F13: =IFERROR(D13*E13,"") -> 0 | G13: =IFERROR(INDEX('Bibliothèque MP INRA'!$I:$I,MATCH($A13,'Bibliothèque MP INRA'!$C:$C,0)),"") -> 0 | H13: =IFERROR(D13*G13/100,"") -> 0 | I13: =IFERROR(INDEX('Bibliothèque MP INRA'!$G:$G,MATCH($A13,'Bibliothèque MP INRA'!$C:$C,0)),"") -> 0 | J13: =IFERROR(D13*I13,"") -> 0 | K13: =IFERROR(INDEX('Bibliothèque MP INRA'!$H:$H,MATCH($A13,'Bibliothèque MP INRA'!$C:$C,0)),"") -> 0 | L13: =IFERROR(D13*K13,"") -> 0 | M13: =IFERROR(INDEX('Bibliothèque MP INRA'!$J:$J,MATCH($A13,'Bibliothèque MP INRA'!$C:$C,0)),"") -> 0 | N13: =IFERROR(D13*M13/100,"") -> 0 | O13: =IFERROR(INDEX('Bibliothèque MP INRA'!$K:$K,MATCH($A13,'Bibliothèque MP INRA'!$C:$C,0)),"") -> 0 | P13: =IFERROR(D13*O13/100,"") -> 0 | Q13: =IFERROR(INDEX('Bibliothèque MP INRA'!$L:$L,MATCH($A13,'Bibliothèque MP INRA'!$C:$C,0)),"") -> 0 | R13: =IFERROR(D13*Q13/100,"") -> 0 | S13: =IFERROR(INDEX('Bibliothèque MP INRA'!$M:$M,MATCH($A13,'Bibliothèque MP INRA'!$C:$C,0)),"") -> 0 | T13: =IFERROR(D13*S13/100,"") -> 0 | U13: =IFERROR(INDEX('Bibliothèque MP INRA'!$N:$N,MATCH($A13,'Bibliothèque MP INRA'!$C:$C,0)),"") -> 0 | V13: =IFERROR(D13*U13/100,"") -> 0 | W13: =IFERROR(INDEX('Bibliothèque MP INRA'!$O:$O,MATCH($A13,'Bibliothèque MP INRA'!$C:$C,0)),"") -> 25 | X13: =IFERROR(D13*W13,"") -> 0 | Y13: =IFERROR(INDEX('Bibliothèque MP INRA'!$P:$P,MATCH($A13,'Bibliothèque MP INRA'!$C:$C,0)),"") -> 5 | Z13: =IFERROR(D13*Y13/100,"") -> 0 | AA13: =IFERROR(INDEX('Bibliothèque MP INRA'!$R:$R,MATCH($A13,'Bibliothèque MP INRA'!$C:$C,0)),"") -> 0 | AB13: =IFERROR(D13*AA13/100,"") -> 0 | AC13: =IFERROR(INDEX('Bibliothèque MP INRA'!$Q:$Q,MATCH($A13,'Bibliothèque MP INRA'!$C:$C,0)),"") -> 0 | AD13: =IFERROR(D13*AC13/100,"") -> 0 | AE13: =IFERROR(INDEX('Bibliothèque MP INRA'!$S:$S,MATCH($A13,'Bibliothèque MP INRA'!$C:$C,0)),"") -> 0 | AF13: =IFERROR($B13*AE13/1000,"") -> 0
C14: =IFERROR(INDEX('Bibliothèque MP INRA'!$D:$D,MATCH($A14,'Bibliothèque MP INRA'!$C:$C,0)),"") | D14: =IFERROR($B14*C14/100,"") | E14: =IFERROR(INDEX('Bibliothèque MP INRA'!$E:$E,MATCH($A14,'Bibliothèque MP INRA'!$C:$C,0)),"") | F14: =IFERROR(D14*E14,"") | G14: =IFERROR(INDEX('Bibliothèque MP INRA'!$I:$I,MATCH($A14,'Bibliothèque MP INRA'!$C:$C,0)),"") | H14: =IFERROR(D14*G14/100,"") | I14: =IFERROR(INDEX('Bibliothèque MP INRA'!$G:$G,MATCH($A14,'Bibliothèque MP INRA'!$C:$C,0)),"") | J14: =IFERROR(D14*I14,"") | K14: =IFERROR(INDEX('Bibliothèque MP INRA'!$H:$H,MATCH($A14,'Bibliothèque MP INRA'!$C:$C,0)),"") | L14: =IFERROR(D14*K14,"") | M14: =IFERROR(INDEX('Bibliothèque MP INRA'!$J:$J,MATCH($A14,'Bibliothèque MP INRA'!$C:$C,0)),"") | N14: =IFERROR(D14*M14/100,"") | O14: =IFERROR(INDEX('Bibliothèque MP INRA'!$K:$K,MATCH($A14,'Bibliothèque MP INRA'!$C:$C,0)),"") | P14: =IFERROR(D14*O14/100,"") | Q14: =IFERROR(INDEX('Bibliothèque MP INRA'!$L:$L,MATCH($A14,'Bibliothèque MP INRA'!$C:$C,0)),"") | R14: =IFERROR(D14*Q14/100,"") | S14: =IFERROR(INDEX('Bibliothèque MP INRA'!$M:$M,MATCH($A14,'Bibliothèque MP INRA'!$C:$C,0)),"") | T14: =IFERROR(D14*S14/100,"") | U14: =IFERROR(INDEX('Bibliothèque MP INRA'!$N:$N,MATCH($A14,'Bibliothèque MP INRA'!$C:$C,0)),"") | V14: =IFERROR(D14*U14/100,"") | W14: =IFERROR(INDEX('Bibliothèque MP INRA'!$O:$O,MATCH($A14,'Bibliothèque MP INRA'!$C:$C,0)),"") | X14: =IFERROR(D14*W14/100,"") | Y14: =IFERROR(INDEX('Bibliothèque MP INRA'!$P:$P,MATCH($A14,'Bibliothèque MP INRA'!$C:$C,0)),"") | Z14: =IFERROR(D14*Y14/100,"") | AA14: =IFERROR(INDEX('Bibliothèque MP INRA'!$R:$R,MATCH($A14,'Bibliothèque MP INRA'!$C:$C,0)),"") | AB14: =IFERROR(D14*AA14/100,"") | AC14: =IFERROR(INDEX('Bibliothèque MP INRA'!$Q:$Q,MATCH($A14,'Bibliothèque MP INRA'!$C:$C,0)),"") | AD14: =IFERROR(D14*AC14/100,"") | AE14: =IFERROR(INDEX('Bibliothèque MP INRA'!$S:$S,MATCH($A14,'Bibliothèque MP INRA'!$C:$C,0)),"") | AF14: =IFERROR($B14*AE14/1000,"")
C15: =IFERROR(INDEX('Bibliothèque MP INRA'!$D:$D,MATCH($A15,'Bibliothèque MP INRA'!$C:$C,0)),"") | D15: =IFERROR($B15*C15/100,"") | E15: =IFERROR(INDEX('Bibliothèque MP INRA'!$E:$E,MATCH($A15,'Bibliothèque MP INRA'!$C:$C,0)),"") | F15: =IFERROR(D15*E15,"") | G15: =IFERROR(INDEX('Bibliothèque MP INRA'!$I:$I,MATCH($A15,'Bibliothèque MP INRA'!$C:$C,0)),"") | H15: =IFERROR(D15*G15/100,"") | I15: =IFERROR(INDEX('Bibliothèque MP INRA'!$G:$G,MATCH($A15,'Bibliothèque MP INRA'!$C:$C,0)),"") | J15: =IFERROR(D15*I15,"") | K15: =IFERROR(INDEX('Bibliothèque MP INRA'!$H:$H,MATCH($A15,'Bibliothèque MP INRA'!$C:$C,0)),"") | L15: =IFERROR(D15*K15,"") | M15: =IFERROR(INDEX('Bibliothèque MP INRA'!$J:$J,MATCH($A15,'Bibliothèque MP INRA'!$C:$C,0)),"") | N15: =IFERROR(D15*M15/100,"") | O15: =IFERROR(INDEX('Bibliothèque MP INRA'!$K:$K,MATCH($A15,'Bibliothèque MP INRA'!$C:$C,0)),"") | P15: =IFERROR(D15*O15/100,"") | Q15: =IFERROR(INDEX('Bibliothèque MP INRA'!$L:$L,MATCH($A15,'Bibliothèque MP INRA'!$C:$C,0)),"") | R15: =IFERROR(D15*Q15/100,"") | S15: =IFERROR(INDEX('Bibliothèque MP INRA'!$M:$M,MATCH($A15,'Bibliothèque MP INRA'!$C:$C,0)),"") | T15: =IFERROR(D15*S15/100,"") | U15: =IFERROR(INDEX('Bibliothèque MP INRA'!$N:$N,MATCH($A15,'Bibliothèque MP INRA'!$C:$C,0)),"") | V15: =IFERROR(D15*U15/100,"") | W15: =IFERROR(INDEX('Bibliothèque MP INRA'!$O:$O,MATCH($A15,'Bibliothèque MP INRA'!$C:$C,0)),"") | X15: =IFERROR(D15*W15/100,"") | Y15: =IFERROR(INDEX('Bibliothèque MP INRA'!$P:$P,MATCH($A15,'Bibliothèque MP INRA'!$C:$C,0)),"") | Z15: =IFERROR(D15*Y15/100,"") | AA15: =IFERROR(INDEX('Bibliothèque MP INRA'!$R:$R,MATCH($A15,'Bibliothèque MP INRA'!$C:$C,0)),"") | AB15: =IFERROR(D15*AA15/100,"") | AC15: =IFERROR(INDEX('Bibliothèque MP INRA'!$Q:$Q,MATCH($A15,'Bibliothèque MP INRA'!$C:$C,0)),"") | AD15: =IFERROR(D15*AC15/100,"") | AE15: =IFERROR(INDEX('Bibliothèque MP INRA'!$S:$S,MATCH($A15,'Bibliothèque MP INRA'!$C:$C,0)),"") | AF15: =IFERROR($B15*AE15/1000,"")
C16: =IFERROR(INDEX('Bibliothèque MP INRA'!$D:$D,MATCH($A16,'Bibliothèque MP INRA'!$C:$C,0)),"") | D16: =IFERROR($B16*C16/100,"") | E16: =IFERROR(INDEX('Bibliothèque MP INRA'!$E:$E,MATCH($A16,'Bibliothèque MP INRA'!$C:$C,0)),"") | F16: =IFERROR(D16*E16,"") | G16: =IFERROR(INDEX('Bibliothèque MP INRA'!$I:$I,MATCH($A16,'Bibliothèque MP INRA'!$C:$C,0)),"") | H16: =IFERROR(D16*G16/100,"") | I16: =IFERROR(INDEX('Bibliothèque MP INRA'!$G:$G,MATCH($A16,'Bibliothèque MP INRA'!$C:$C,0)),"") | J16: =IFERROR(D16*I16,"") | K16: =IFERROR(INDEX('Bibliothèque MP INRA'!$H:$H,MATCH($A16,'Bibliothèque MP INRA'!$C:$C,0)),"") | L16: =IFERROR(D16*K16,"") | M16: =IFERROR(INDEX('Bibliothèque MP INRA'!$J:$J,MATCH($A16,'Bibliothèque MP INRA'!$C:$C,0)),"") | N16: =IFERROR(D16*M16/100,"") | O16: =IFERROR(INDEX('Bibliothèque MP INRA'!$K:$K,MATCH($A16,'Bibliothèque MP INRA'!$C:$C,0)),"") | P16: =IFERROR(D16*O16/100,"") | Q16: =IFERROR(INDEX('Bibliothèque MP INRA'!$L:$L,MATCH($A16,'Bibliothèque MP INRA'!$C:$C,0)),"") | R16: =IFERROR(D16*Q16/100,"") | S16: =IFERROR(INDEX('Bibliothèque MP INRA'!$M:$M,MATCH($A16,'Bibliothèque MP INRA'!$C:$C,0)),"") | T16: =IFERROR(D16*S16/100,"") | U16: =IFERROR(INDEX('Bibliothèque MP INRA'!$N:$N,MATCH($A16,'Bibliothèque MP INRA'!$C:$C,0)),"") | V16: =IFERROR(D16*U16/100,"") | W16: =IFERROR(INDEX('Bibliothèque MP INRA'!$O:$O,MATCH($A16,'Bibliothèque MP INRA'!$C:$C,0)),"") | X16: =IFERROR(D16*W16/100,"") | Y16: =IFERROR(INDEX('Bibliothèque MP INRA'!$P:$P,MATCH($A16,'Bibliothèque MP INRA'!$C:$C,0)),"") | Z16: =IFERROR(D16*Y16/100,"") | AA16: =IFERROR(INDEX('Bibliothèque MP INRA'!$R:$R,MATCH($A16,'Bibliothèque MP INRA'!$C:$C,0)),"") | AB16: =IFERROR(D16*AA16/100,"") | AC16: =IFERROR(INDEX('Bibliothèque MP INRA'!$Q:$Q,MATCH($A16,'Bibliothèque MP INRA'!$C:$C,0)),"") | AD16: =IFERROR(D16*AC16/100,"") | AE16: =IFERROR(INDEX('Bibliothèque MP INRA'!$S:$S,MATCH($A16,'Bibliothèque MP INRA'!$C:$C,0)),"") | AF16: =IFERROR($B16*AE16/1000,"")
C17: =IFERROR(INDEX('Bibliothèque MP INRA'!$D:$D,MATCH($A17,'Bibliothèque MP INRA'!$C:$C,0)),"") | D17: =IFERROR($B17*C17/100,"") | E17: =IFERROR(INDEX('Bibliothèque MP INRA'!$E:$E,MATCH($A17,'Bibliothèque MP INRA'!$C:$C,0)),"") | F17: =IFERROR(D17*E17,"") | G17: =IFERROR(INDEX('Bibliothèque MP INRA'!$I:$I,MATCH($A17,'Bibliothèque MP INRA'!$C:$C,0)),"") | H17: =IFERROR(D17*G17/100,"") | I17: =IFERROR(INDEX('Bibliothèque MP INRA'!$G:$G,MATCH($A17,'Bibliothèque MP INRA'!$C:$C,0)),"") | J17: =IFERROR(D17*I17,"") | K17: =IFERROR(INDEX('Bibliothèque MP INRA'!$H:$H,MATCH($A17,'Bibliothèque MP INRA'!$C:$C,0)),"") | L17: =IFERROR(D17*K17,"") | M17: =IFERROR(INDEX('Bibliothèque MP INRA'!$J:$J,MATCH($A17,'Bibliothèque MP INRA'!$C:$C,0)),"") | N17: =IFERROR(D17*M17/100,"") | O17: =IFERROR(INDEX('Bibliothèque MP INRA'!$K:$K,MATCH($A17,'Bibliothèque MP INRA'!$C:$C,0)),"") | P17: =IFERROR(D17*O17/100,"") | Q17: =IFERROR(INDEX('Bibliothèque MP INRA'!$L:$L,MATCH($A17,'Bibliothèque MP INRA'!$C:$C,0)),"") | R17: =IFERROR(D17*Q17/100,"") | S17: =IFERROR(INDEX('Bibliothèque MP INRA'!$M:$M,MATCH($A17,'Bibliothèque MP INRA'!$C:$C,0)),"") | T17: =IFERROR(D17*S17/100,"") | U17: =IFERROR(INDEX('Bibliothèque MP INRA'!$N:$N,MATCH($A17,'Bibliothèque MP INRA'!$C:$C,0)),"") | V17: =IFERROR(D17*U17/100,"") | W17: =IFERROR(INDEX('Bibliothèque MP INRA'!$O:$O,MATCH($A17,'Bibliothèque MP INRA'!$C:$C,0)),"") | X17: =IFERROR(D17*W17/100,"") | Y17: =IFERROR(INDEX('Bibliothèque MP INRA'!$P:$P,MATCH($A17,'Bibliothèque MP INRA'!$C:$C,0)),"") | Z17: =IFERROR(D17*Y17/100,"") | AA17: =IFERROR(INDEX('Bibliothèque MP INRA'!$R:$R,MATCH($A17,'Bibliothèque MP INRA'!$C:$C,0)),"") | AB17: =IFERROR(D17*AA17/100,"") | AC17: =IFERROR(INDEX('Bibliothèque MP INRA'!$Q:$Q,MATCH($A17,'Bibliothèque MP INRA'!$C:$C,0)),"") | AD17: =IFERROR(D17*AC17/100,"") | AE17: =IFERROR(INDEX('Bibliothèque MP INRA'!$S:$S,MATCH($A17,'Bibliothèque MP INRA'!$C:$C,0)),"") | AF17: =IFERROR($B17*AE17/1000,"")
C18: =IFERROR(INDEX('Bibliothèque MP INRA'!$D:$D,MATCH($A18,'Bibliothèque MP INRA'!$C:$C,0)),"") | D18: =IFERROR($B18*C18/100,"") | E18: =IFERROR(INDEX('Bibliothèque MP INRA'!$E:$E,MATCH($A18,'Bibliothèque MP INRA'!$C:$C,0)),"") | F18: =IFERROR(D18*E18,"") | G18: =IFERROR(INDEX('Bibliothèque MP INRA'!$I:$I,MATCH($A18,'Bibliothèque MP INRA'!$C:$C,0)),"") | H18: =IFERROR(D18*G18/100,"") | I18: =IFERROR(INDEX('Bibliothèque MP INRA'!$G:$G,MATCH($A18,'Bibliothèque MP INRA'!$C:$C,0)),"") | J18: =IFERROR(D18*I18,"") | K18: =IFERROR(INDEX('Bibliothèque MP INRA'!$H:$H,MATCH($A18,'Bibliothèque MP INRA'!$C:$C,0)),"") | L18: =IFERROR(D18*K18,"") | M18: =IFERROR(INDEX('Bibliothèque MP INRA'!$J:$J,MATCH($A18,'Bibliothèque MP INRA'!$C:$C,0)),"") | N18: =IFERROR(D18*M18/100,"") | O18: =IFERROR(INDEX('Bibliothèque MP INRA'!$K:$K,MATCH($A18,'Bibliothèque MP INRA'!$C:$C,0)),"") | P18: =IFERROR(D18*O18/100,"") | Q18: =IFERROR(INDEX('Bibliothèque MP INRA'!$L:$L,MATCH($A18,'Bibliothèque MP INRA'!$C:$C,0)),"") | R18: =IFERROR(D18*Q18/100,"") | S18: =IFERROR(INDEX('Bibliothèque MP INRA'!$M:$M,MATCH($A18,'Bibliothèque MP INRA'!$C:$C,0)),"") | T18: =IFERROR(D18*S18/100,"") | U18: =IFERROR(INDEX('Bibliothèque MP INRA'!$N:$N,MATCH($A18,'Bibliothèque MP INRA'!$C:$C,0)),"") | V18: =IFERROR(D18*U18/100,"") | W18: =IFERROR(INDEX('Bibliothèque MP INRA'!$O:$O,MATCH($A18,'Bibliothèque MP INRA'!$C:$C,0)),"") | X18: =IFERROR(D18*W18/100,"") | Y18: =IFERROR(INDEX('Bibliothèque MP INRA'!$P:$P,MATCH($A18,'Bibliothèque MP INRA'!$C:$C,0)),"") | Z18: =IFERROR(D18*Y18/100,"") | AA18: =IFERROR(INDEX('Bibliothèque MP INRA'!$R:$R,MATCH($A18,'Bibliothèque MP INRA'!$C:$C,0)),"") | AB18: =IFERROR(D18*AA18/100,"") | AC18: =IFERROR(INDEX('Bibliothèque MP INRA'!$Q:$Q,MATCH($A18,'Bibliothèque MP INRA'!$C:$C,0)),"") | AD18: =IFERROR(D18*AC18/100,"") | AE18: =IFERROR(INDEX('Bibliothèque MP INRA'!$S:$S,MATCH($A18,'Bibliothèque MP INRA'!$C:$C,0)),"") | AF18: =IFERROR($B18*AE18/1000,"")
C19: =IFERROR(INDEX('Bibliothèque MP INRA'!$D:$D,MATCH($A19,'Bibliothèque MP INRA'!$C:$C,0)),"") | D19: =IFERROR($B19*C19/100,"") | E19: =IFERROR(INDEX('Bibliothèque MP INRA'!$E:$E,MATCH($A19,'Bibliothèque MP INRA'!$C:$C,0)),"") | F19: =IFERROR(D19*E19,"") | G19: =IFERROR(INDEX('Bibliothèque MP INRA'!$I:$I,MATCH($A19,'Bibliothèque MP INRA'!$C:$C,0)),"") | H19: =IFERROR(D19*G19/100,"") | I19: =IFERROR(INDEX('Bibliothèque MP INRA'!$G:$G,MATCH($A19,'Bibliothèque MP INRA'!$C:$C,0)),"") | J19: =IFERROR(D19*I19,"") | K19: =IFERROR(INDEX('Bibliothèque MP INRA'!$H:$H,MATCH($A19,'Bibliothèque MP INRA'!$C:$C,0)),"") | L19: =IFERROR(D19*K19,"") | M19: =IFERROR(INDEX('Bibliothèque MP INRA'!$J:$J,MATCH($A19,'Bibliothèque MP INRA'!$C:$C,0)),"") | N19: =IFERROR(D19*M19/100,"") | O19: =IFERROR(INDEX('Bibliothèque MP INRA'!$K:$K,MATCH($A19,'Bibliothèque MP INRA'!$C:$C,0)),"") | P19: =IFERROR(D19*O19/100,"") | Q19: =IFERROR(INDEX('Bibliothèque MP INRA'!$L:$L,MATCH($A19,'Bibliothèque MP INRA'!$C:$C,0)),"") | R19: =IFERROR(D19*Q19/100,"") | S19: =IFERROR(INDEX('Bibliothèque MP INRA'!$M:$M,MATCH($A19,'Bibliothèque MP INRA'!$C:$C,0)),"") | T19: =IFERROR(D19*S19/100,"") | U19: =IFERROR(INDEX('Bibliothèque MP INRA'!$N:$N,MATCH($A19,'Bibliothèque MP INRA'!$C:$C,0)),"") | V19: =IFERROR(D19*U19/100,"") | W19: =IFERROR(INDEX('Bibliothèque MP INRA'!$O:$O,MATCH($A19,'Bibliothèque MP INRA'!$C:$C,0)),"") | X19: =IFERROR(D19*W19/100,"") | Y19: =IFERROR(INDEX('Bibliothèque MP INRA'!$P:$P,MATCH($A19,'Bibliothèque MP INRA'!$C:$C,0)),"") | Z19: =IFERROR(D19*Y19/100,"") | AA19: =IFERROR(INDEX('Bibliothèque MP INRA'!$R:$R,MATCH($A19,'Bibliothèque MP INRA'!$C:$C,0)),"") | AB19: =IFERROR(D19*AA19/100,"") | AC19: =IFERROR(INDEX('Bibliothèque MP INRA'!$Q:$Q,MATCH($A19,'Bibliothèque MP INRA'!$C:$C,0)),"") | AD19: =IFERROR(D19*AC19/100,"") | AE19: =IFERROR(INDEX('Bibliothèque MP INRA'!$S:$S,MATCH($A19,'Bibliothèque MP INRA'!$C:$C,0)),"") | AF19: =IFERROR($B19*AE19/1000,"")
C20: =IFERROR(INDEX('Bibliothèque MP INRA'!$D:$D,MATCH($A20,'Bibliothèque MP INRA'!$C:$C,0)),"") | D20: =IFERROR($B20*C20/100,"") | E20: =IFERROR(INDEX('Bibliothèque MP INRA'!$E:$E,MATCH($A20,'Bibliothèque MP INRA'!$C:$C,0)),"") | F20: =IFERROR(D20*E20,"") | G20: =IFERROR(INDEX('Bibliothèque MP INRA'!$I:$I,MATCH($A20,'Bibliothèque MP INRA'!$C:$C,0)),"") | H20: =IFERROR(D20*G20/100,"") | I20: =IFERROR(INDEX('Bibliothèque MP INRA'!$G:$G,MATCH($A20,'Bibliothèque MP INRA'!$C:$C,0)),"") | J20: =IFERROR(D20*I20,"") | K20: =IFERROR(INDEX('Bibliothèque MP INRA'!$H:$H,MATCH($A20,'Bibliothèque MP INRA'!$C:$C,0)),"") | L20: =IFERROR(D20*K20,"") | M20: =IFERROR(INDEX('Bibliothèque MP INRA'!$J:$J,MATCH($A20,'Bibliothèque MP INRA'!$C:$C,0)),"") | N20: =IFERROR(D20*M20/100,"") | O20: =IFERROR(INDEX('Bibliothèque MP INRA'!$K:$K,MATCH($A20,'Bibliothèque MP INRA'!$C:$C,0)),"") | P20: =IFERROR(D20*O20/100,"") | Q20: =IFERROR(INDEX('Bibliothèque MP INRA'!$L:$L,MATCH($A20,'Bibliothèque MP INRA'!$C:$C,0)),"") | R20: =IFERROR(D20*Q20/100,"") | S20: =IFERROR(INDEX('Bibliothèque MP INRA'!$M:$M,MATCH($A20,'Bibliothèque MP INRA'!$C:$C,0)),"") | T20: =IFERROR(D20*S20/100,"") | U20: =IFERROR(INDEX('Bibliothèque MP INRA'!$N:$N,MATCH($A20,'Bibliothèque MP INRA'!$C:$C,0)),"") | V20: =IFERROR(D20*U20/100,"") | W20: =IFERROR(INDEX('Bibliothèque MP INRA'!$O:$O,MATCH($A20,'Bibliothèque MP INRA'!$C:$C,0)),"") | X20: =IFERROR(D20*W20/100,"") | Y20: =IFERROR(INDEX('Bibliothèque MP INRA'!$P:$P,MATCH($A20,'Bibliothèque MP INRA'!$C:$C,0)),"") | Z20: =IFERROR(D20*Y20/100,"") | AA20: =IFERROR(INDEX('Bibliothèque MP INRA'!$R:$R,MATCH($A20,'Bibliothèque MP INRA'!$C:$C,0)),"") | AB20: =IFERROR(D20*AA20/100,"") | AC20: =IFERROR(INDEX('Bibliothèque MP INRA'!$Q:$Q,MATCH($A20,'Bibliothèque MP INRA'!$C:$C,0)),"") | AD20: =IFERROR(D20*AC20/100,"") | AE20: =IFERROR(INDEX('Bibliothèque MP INRA'!$S:$S,MATCH($A20,'Bibliothèque MP INRA'!$C:$C,0)),"") | AF20: =IFERROR($B20*AE20/1000,"")
C21: =IFERROR(INDEX('Bibliothèque MP INRA'!$D:$D,MATCH($A21,'Bibliothèque MP INRA'!$C:$C,0)),"") | D21: =IFERROR($B21*C21/100,"") | E21: =IFERROR(INDEX('Bibliothèque MP INRA'!$E:$E,MATCH($A21,'Bibliothèque MP INRA'!$C:$C,0)),"") | F21: =IFERROR(D21*E21,"") | G21: =IFERROR(INDEX('Bibliothèque MP INRA'!$I:$I,MATCH($A21,'Bibliothèque MP INRA'!$C:$C,0)),"") | H21: =IFERROR(D21*G21/100,"") | I21: =IFERROR(INDEX('Bibliothèque MP INRA'!$G:$G,MATCH($A21,'Bibliothèque MP INRA'!$C:$C,0)),"") | J21: =IFERROR(D21*I21,"") | K21: =IFERROR(INDEX('Bibliothèque MP INRA'!$H:$H,MATCH($A21,'Bibliothèque MP INRA'!$C:$C,0)),"") | L21: =IFERROR(D21*K21,"") | M21: =IFERROR(INDEX('Bibliothèque MP INRA'!$J:$J,MATCH($A21,'Bibliothèque MP INRA'!$C:$C,0)),"") | N21: =IFERROR(D21*M21/100,"") | O21: =IFERROR(INDEX('Bibliothèque MP INRA'!$K:$K,MATCH($A21,'Bibliothèque MP INRA'!$C:$C,0)),"") | P21: =IFERROR(D21*O21/100,"") | Q21: =IFERROR(INDEX('Bibliothèque MP INRA'!$L:$L,MATCH($A21,'Bibliothèque MP INRA'!$C:$C,0)),"") | R21: =IFERROR(D21*Q21/100,"") | S21: =IFERROR(INDEX('Bibliothèque MP INRA'!$M:$M,MATCH($A21,'Bibliothèque MP INRA'!$C:$C,0)),"") | T21: =IFERROR(D21*S21/100,"") | U21: =IFERROR(INDEX('Bibliothèque MP INRA'!$N:$N,MATCH($A21,'Bibliothèque MP INRA'!$C:$C,0)),"") | V21: =IFERROR(D21*U21/100,"") | W21: =IFERROR(INDEX('Bibliothèque MP INRA'!$O:$O,MATCH($A21,'Bibliothèque MP INRA'!$C:$C,0)),"") | X21: =IFERROR(D21*W21/100,"") | Y21: =IFERROR(INDEX('Bibliothèque MP INRA'!$P:$P,MATCH($A21,'Bibliothèque MP INRA'!$C:$C,0)),"") | Z21: =IFERROR(D21*Y21/100,"") | AA21: =IFERROR(INDEX('Bibliothèque MP INRA'!$R:$R,MATCH($A21,'Bibliothèque MP INRA'!$C:$C,0)),"") | AB21: =IFERROR(D21*AA21/100,"") | AC21: =IFERROR(INDEX('Bibliothèque MP INRA'!$Q:$Q,MATCH($A21,'Bibliothèque MP INRA'!$C:$C,0)),"") | AD21: =IFERROR(D21*AC21/100,"") | AE21: =IFERROR(INDEX('Bibliothèque MP INRA'!$S:$S,MATCH($A21,'Bibliothèque MP INRA'!$C:$C,0)),"") | AF21: =IFERROR($B21*AE21/1000,"")
C22: =IFERROR(INDEX('Bibliothèque MP INRA'!$D:$D,MATCH($A22,'Bibliothèque MP INRA'!$C:$C,0)),"") | D22: =IFERROR($B22*C22/100,"") | E22: =IFERROR(INDEX('Bibliothèque MP INRA'!$E:$E,MATCH($A22,'Bibliothèque MP INRA'!$C:$C,0)),"") | F22: =IFERROR(D22*E22,"") | G22: =IFERROR(INDEX('Bibliothèque MP INRA'!$I:$I,MATCH($A22,'Bibliothèque MP INRA'!$C:$C,0)),"") | H22: =IFERROR(D22*G22/100,"") | I22: =IFERROR(INDEX('Bibliothèque MP INRA'!$G:$G,MATCH($A22,'Bibliothèque MP INRA'!$C:$C,0)),"") | J22: =IFERROR(D22*I22,"") | K22: =IFERROR(INDEX('Bibliothèque MP INRA'!$H:$H,MATCH($A22,'Bibliothèque MP INRA'!$C:$C,0)),"") | L22: =IFERROR(D22*K22,"") | M22: =IFERROR(INDEX('Bibliothèque MP INRA'!$J:$J,MATCH($A22,'Bibliothèque MP INRA'!$C:$C,0)),"") | N22: =IFERROR(D22*M22/100,"") | O22: =IFERROR(INDEX('Bibliothèque MP INRA'!$K:$K,MATCH($A22,'Bibliothèque MP INRA'!$C:$C,0)),"") | P22: =IFERROR(D22*O22/100,"") | Q22: =IFERROR(INDEX('Bibliothèque MP INRA'!$L:$L,MATCH($A22,'Bibliothèque MP INRA'!$C:$C,0)),"") | R22: =IFERROR(D22*Q22/100,"") | S22: =IFERROR(INDEX('Bibliothèque MP INRA'!$M:$M,MATCH($A22,'Bibliothèque MP INRA'!$C:$C,0)),"") | T22: =IFERROR(D22*S22/100,"") | U22: =IFERROR(INDEX('Bibliothèque MP INRA'!$N:$N,MATCH($A22,'Bibliothèque MP INRA'!$C:$C,0)),"") | V22: =IFERROR(D22*U22/100,"") | W22: =IFERROR(INDEX('Bibliothèque MP INRA'!$O:$O,MATCH($A22,'Bibliothèque MP INRA'!$C:$C,0)),"") | X22: =IFERROR(D22*W22/100,"") | Y22: =IFERROR(INDEX('Bibliothèque MP INRA'!$P:$P,MATCH($A22,'Bibliothèque MP INRA'!$C:$C,0)),"") | Z22: =IFERROR(D22*Y22/100,"") | AA22: =IFERROR(INDEX('Bibliothèque MP INRA'!$R:$R,MATCH($A22,'Bibliothèque MP INRA'!$C:$C,0)),"") | AB22: =IFERROR(D22*AA22/100,"") | AC22: =IFERROR(INDEX('Bibliothèque MP INRA'!$Q:$Q,MATCH($A22,'Bibliothèque MP INRA'!$C:$C,0)),"") | AD22: =IFERROR(D22*AC22/100,"") | AE22: =IFERROR(INDEX('Bibliothèque MP INRA'!$S:$S,MATCH($A22,'Bibliothèque MP INRA'!$C:$C,0)),"") | AF22: =IFERROR($B22*AE22/1000,"")
C23: =IFERROR(INDEX('Bibliothèque MP INRA'!$D:$D,MATCH($A23,'Bibliothèque MP INRA'!$C:$C,0)),"") | D23: =IFERROR($B23*C23/100,"") | E23: =IFERROR(INDEX('Bibliothèque MP INRA'!$E:$E,MATCH($A23,'Bibliothèque MP INRA'!$C:$C,0)),"") | F23: =IFERROR(D23*E23,"") | G23: =IFERROR(INDEX('Bibliothèque MP INRA'!$I:$I,MATCH($A23,'Bibliothèque MP INRA'!$C:$C,0)),"") | H23: =IFERROR(D23*G23/100,"") | I23: =IFERROR(INDEX('Bibliothèque MP INRA'!$G:$G,MATCH($A23,'Bibliothèque MP INRA'!$C:$C,0)),"") | J23: =IFERROR(D23*I23,"") | K23: =IFERROR(INDEX('Bibliothèque MP INRA'!$H:$H,MATCH($A23,'Bibliothèque MP INRA'!$C:$C,0)),"") | L23: =IFERROR(D23*K23,"") | M23: =IFERROR(INDEX('Bibliothèque MP INRA'!$J:$J,MATCH($A23,'Bibliothèque MP INRA'!$C:$C,0)),"") | N23: =IFERROR(D23*M23/100,"") | O23: =IFERROR(INDEX('Bibliothèque MP INRA'!$K:$K,MATCH($A23,'Bibliothèque MP INRA'!$C:$C,0)),"") | P23: =IFERROR(D23*O23/100,"") | Q23: =IFERROR(INDEX('Bibliothèque MP INRA'!$L:$L,MATCH($A23,'Bibliothèque MP INRA'!$C:$C,0)),"") | R23: =IFERROR(D23*Q23/100,"") | S23: =IFERROR(INDEX('Bibliothèque MP INRA'!$M:$M,MATCH($A23,'Bibliothèque MP INRA'!$C:$C,0)),"") | T23: =IFERROR(D23*S23/100,"") | U23: =IFERROR(INDEX('Bibliothèque MP INRA'!$N:$N,MATCH($A23,'Bibliothèque MP INRA'!$C:$C,0)),"") | V23: =IFERROR(D23*U23/100,"") | W23: =IFERROR(INDEX('Bibliothèque MP INRA'!$O:$O,MATCH($A23,'Bibliothèque MP INRA'!$C:$C,0)),"") | X23: =IFERROR(D23*W23/100,"") | Y23: =IFERROR(INDEX('Bibliothèque MP INRA'!$P:$P,MATCH($A23,'Bibliothèque MP INRA'!$C:$C,0)),"") | Z23: =IFERROR(D23*Y23/100,"") | AA23: =IFERROR(INDEX('Bibliothèque MP INRA'!$R:$R,MATCH($A23,'Bibliothèque MP INRA'!$C:$C,0)),"") | AB23: =IFERROR(D23*AA23/100,"") | AC23: =IFERROR(INDEX('Bibliothèque MP INRA'!$Q:$Q,MATCH($A23,'Bibliothèque MP INRA'!$C:$C,0)),"") | AD23: =IFERROR(D23*AC23/100,"") | AE23: =IFERROR(INDEX('Bibliothèque MP INRA'!$S:$S,MATCH($A23,'Bibliothèque MP INRA'!$C:$C,0)),"") | AF23: =IFERROR($B23*AE23/1000,"")
C24: =IFERROR(INDEX('Bibliothèque MP INRA'!$D:$D,MATCH($A24,'Bibliothèque MP INRA'!$C:$C,0)),"") | D24: =IFERROR($B24*C24/100,"") | E24: =IFERROR(INDEX('Bibliothèque MP INRA'!$E:$E,MATCH($A24,'Bibliothèque MP INRA'!$C:$C,0)),"") | F24: =IFERROR(D24*E24,"") | G24: =IFERROR(INDEX('Bibliothèque MP INRA'!$I:$I,MATCH($A24,'Bibliothèque MP INRA'!$C:$C,0)),"") | H24: =IFERROR(D24*G24/100,"") | I24: =IFERROR(INDEX('Bibliothèque MP INRA'!$G:$G,MATCH($A24,'Bibliothèque MP INRA'!$C:$C,0)),"") | J24: =IFERROR(D24*I24,"") | K24: =IFERROR(INDEX('Bibliothèque MP INRA'!$H:$H,MATCH($A24,'Bibliothèque MP INRA'!$C:$C,0)),"") | L24: =IFERROR(D24*K24,"") | M24: =IFERROR(INDEX('Bibliothèque MP INRA'!$J:$J,MATCH($A24,'Bibliothèque MP INRA'!$C:$C,0)),"") | N24: =IFERROR(D24*M24/100,"") | O24: =IFERROR(INDEX('Bibliothèque MP INRA'!$K:$K,MATCH($A24,'Bibliothèque MP INRA'!$C:$C,0)),"") | P24: =IFERROR(D24*O24/100,"") | Q24: =IFERROR(INDEX('Bibliothèque MP INRA'!$L:$L,MATCH($A24,'Bibliothèque MP INRA'!$C:$C,0)),"") | R24: =IFERROR(D24*Q24/100,"") | S24: =IFERROR(INDEX('Bibliothèque MP INRA'!$M:$M,MATCH($A24,'Bibliothèque MP INRA'!$C:$C,0)),"") | T24: =IFERROR(D24*S24/100,"") | U24: =IFERROR(INDEX('Bibliothèque MP INRA'!$N:$N,MATCH($A24,'Bibliothèque MP INRA'!$C:$C,0)),"") | V24: =IFERROR(D24*U24/100,"") | W24: =IFERROR(INDEX('Bibliothèque MP INRA'!$O:$O,MATCH($A24,'Bibliothèque MP INRA'!$C:$C,0)),"") | X24: =IFERROR(D24*W24/100,"") | Y24: =IFERROR(INDEX('Bibliothèque MP INRA'!$P:$P,MATCH($A24,'Bibliothèque MP INRA'!$C:$C,0)),"") | Z24: =IFERROR(D24*Y24/100,"") | AA24: =IFERROR(INDEX('Bibliothèque MP INRA'!$R:$R,MATCH($A24,'Bibliothèque MP INRA'!$C:$C,0)),"") | AB24: =IFERROR(D24*AA24/100,"") | AC24: =IFERROR(INDEX('Bibliothèque MP INRA'!$Q:$Q,MATCH($A24,'Bibliothèque MP INRA'!$C:$C,0)),"") | AD24: =IFERROR(D24*AC24/100,"") | AE24: =IFERROR(INDEX('Bibliothèque MP INRA'!$S:$S,MATCH($A24,'Bibliothèque MP INRA'!$C:$C,0)),"") | AF24: =IFERROR($B24*AE24/1000,"")
C25: =IFERROR(INDEX('Bibliothèque MP INRA'!$D:$D,MATCH($A25,'Bibliothèque MP INRA'!$C:$C,0)),"") | D25: =IFERROR($B25*C25/100,"") | E25: =IFERROR(INDEX('Bibliothèque MP INRA'!$E:$E,MATCH($A25,'Bibliothèque MP INRA'!$C:$C,0)),"") | F25: =IFERROR(D25*E25,"") | G25: =IFERROR(INDEX('Bibliothèque MP INRA'!$I:$I,MATCH($A25,'Bibliothèque MP INRA'!$C:$C,0)),"") | H25: =IFERROR(D25*G25/100,"") | I25: =IFERROR(INDEX('Bibliothèque MP INRA'!$G:$G,MATCH($A25,'Bibliothèque MP INRA'!$C:$C,0)),"") | J25: =IFERROR(D25*I25,"") | K25: =IFERROR(INDEX('Bibliothèque MP INRA'!$H:$H,MATCH($A25,'Bibliothèque MP INRA'!$C:$C,0)),"") | L25: =IFERROR(D25*K25,"") | M25: =IFERROR(INDEX('Bibliothèque MP INRA'!$J:$J,MATCH($A25,'Bibliothèque MP INRA'!$C:$C,0)),"") | N25: =IFERROR(D25*M25/100,"") | O25: =IFERROR(INDEX('Bibliothèque MP INRA'!$K:$K,MATCH($A25,'Bibliothèque MP INRA'!$C:$C,0)),"") | P25: =IFERROR(D25*O25/100,"") | Q25: =IFERROR(INDEX('Bibliothèque MP INRA'!$L:$L,MATCH($A25,'Bibliothèque MP INRA'!$C:$C,0)),"") | R25: =IFERROR(D25*Q25/100,"") | S25: =IFERROR(INDEX('Bibliothèque MP INRA'!$M:$M,MATCH($A25,'Bibliothèque MP INRA'!$C:$C,0)),"") | T25: =IFERROR(D25*S25/100,"") | U25: =IFERROR(INDEX('Bibliothèque MP INRA'!$N:$N,MATCH($A25,'Bibliothèque MP INRA'!$C:$C,0)),"") | V25: =IFERROR(D25*U25/100,"") | W25: =IFERROR(INDEX('Bibliothèque MP INRA'!$O:$O,MATCH($A25,'Bibliothèque MP INRA'!$C:$C,0)),"") | X25: =IFERROR(D25*W25/100,"") | Y25: =IFERROR(INDEX('Bibliothèque MP INRA'!$P:$P,MATCH($A25,'Bibliothèque MP INRA'!$C:$C,0)),"") | Z25: =IFERROR(D25*Y25/100,"") | AA25: =IFERROR(INDEX('Bibliothèque MP INRA'!$R:$R,MATCH($A25,'Bibliothèque MP INRA'!$C:$C,0)),"") | AB25: =IFERROR(D25*AA25/100,"") | AC25: =IFERROR(INDEX('Bibliothèque MP INRA'!$Q:$Q,MATCH($A25,'Bibliothèque MP INRA'!$C:$C,0)),"") | AD25: =IFERROR(D25*AC25/100,"") | AE25: =IFERROR(INDEX('Bibliothèque MP INRA'!$S:$S,MATCH($A25,'Bibliothèque MP INRA'!$C:$C,0)),"") | AF25: =IFERROR($B25*AE25/1000,"")
... C33: =IFERROR(INDEX('Bibliothèque MP INRA'!$D:$D,MATCH($A33,'Bibliothèque MP INRA'!$C:$C,0)),"") | D33: =IFERROR($B33*C33/100,"") | E33: =IFERROR(INDEX('Bibliothèque MP INRA'!$E:$E,MATCH($A33,'Bibliothèque MP INRA'!$C:$C,0)),"") | F33: =IFERROR(D33*E33,"") | G33: =IFERROR(INDEX('Bibliothèque MP INRA'!$I:$I,MATCH($A33,'Bibliothèque MP INRA'!$C:$C,0)),"") | H33: =IFERROR(D33*G33/100,"") | I33: =IFERROR(INDEX('Bibliothèque MP INRA'!$G:$G,MATCH($A33,'Bibliothèque MP INRA'!$C:$C,0)),"") | J33: =IFERROR(D33*I33,"") | K33: =IFERROR(INDEX('Bibliothèque MP INRA'!$H:$H,MATCH($A33,'Bibliothèque MP INRA'!$C:$C,0)),"") | L33: =IFERROR(D33*K33,"") | M33: =IFERROR(INDEX('Bibliothèque MP INRA'!$J:$J,MATCH($A33,'Bibliothèque MP INRA'!$C:$C,0)),"") | N33: =IFERROR(D33*M33/100,"") | O33: =IFERROR(INDEX('Bibliothèque MP INRA'!$K:$K,MATCH($A33,'Bibliothèque MP INRA'!$C:$C,0)),"") | P33: =IFERROR(D33*O33/100,"") | Q33: =IFERROR(INDEX('Bibliothèque MP INRA'!$L:$L,MATCH($A33,'Bibliothèque MP INRA'!$C:$C,0)),"") | R33: =IFERROR(D33*Q33/100,"") | S33: =IFERROR(INDEX('Bibliothèque MP INRA'!$M:$M,MATCH($A33,'Bibliothèque MP INRA'!$C:$C,0)),"") | T33: =IFERROR(D33*S33/100,"") | U33: =IFERROR(INDEX('Bibliothèque MP INRA'!$N:$N,MATCH($A33,'Bibliothèque MP INRA'!$C:$C,0)),"") | V33: =IFERROR(D33*U33/100,"") | W33: =IFERROR(INDEX('Bibliothèque MP INRA'!$O:$O,MATCH($A33,'Bibliothèque MP INRA'!$C:$C,0)),"") | X33: =IFERROR(D33*W33/100,"") | Y33: =IFERROR(INDEX('Bibliothèque MP INRA'!$P:$P,MATCH($A33,'Bibliothèque MP INRA'!$C:$C,0)),"") | Z33: =IFERROR(D33*Y33/100,"") | AA33: =IFERROR(INDEX('Bibliothèque MP INRA'!$R:$R,MATCH($A33,'Bibliothèque MP INRA'!$C:$C,0)),"") | AB33: =IFERROR(D33*AA33/100,"") | AC33: =IFERROR(INDEX('Bibliothèque MP INRA'!$Q:$Q,MATCH($A33,'Bibliothèque MP INRA'!$C:$C,0)),"") | AD33: =IFERROR(D33*AC33/100,"") | AE33: =IFERROR(INDEX('Bibliothèque MP INRA'!$S:$S,MATCH($A33,'Bibliothèque MP INRA'!$C:$C,0)),"") | AF33: =IFERROR($B33*AE33/1000,"")
A35: TOTAL / MOYENNES | B35: =SUM(B4:B34) -> 32.28 | C35: =IFERROR(AVERAGE(C4:C33),"") -> 86.3 | D35: =SUM(D4:D33) -> 14.71 | E35: =IFERROR(AVERAGE(E4:E33),"") -> 0.681 | F35: =SUM(F4:F33) -> 13.6656 | G35: =IFERROR(AVERAGE(G4:G33),"") -> 9.7 | H35: =SUM(H4:H33) -> 1.6514 | I35: =IFERROR(AVERAGE(I4:I33),"") -> 57.2 | J35: =SUM(J4:J33) -> 1057.34 | K35: =IFERROR(AVERAGE(K4:K33),"") -> 64.5 | L35: =SUM(L4:L33) -> 1317.16 | M35: =IFERROR(AVERAGE(M4:M33),"") -> 22.7 | N35: =SUM(N4:N33) -> 4.4338 | O35: =IFERROR(AVERAGE(O4:O33),"") -> 2 | P35: =SUM(P4:P33) -> 0.4242 | Q35: =IFERROR(AVERAGE(Q4:Q33),"") -> 19.8 | R35: =SUM(R4:R33) -> 5.0038 | S35: =IFERROR(AVERAGE(S4:S33),"") -> 11.3 | T35: =SUM(T4:T33) -> 2.89 | U35: =IFERROR(AVERAGE(U4:U33),"") -> 1.78 | V35: =SUM(V4:V33) -> 0.42175 | W35: =IFERROR(AVERAGE(W4:W33),"") -> 2.617 | X35: =SUM(X4:X34)*10 -> 29.6952 | Y35: =IFERROR(AVERAGE(Y4:Y33),"") -> 0.713 | Z35: =SUM(Z4:Z33)*1000 -> 37.908 | AA35: =IFERROR(AVERAGE(AA4:AA33),"") -> 0.016 | AB35: =SUM(AB4:AB33)*1000 -> 3.153 | AC35: =IFERROR(AVERAGE(AC4:AC33),"") -> 0.61 | AD35: =SUM(AD4:AD33)*1000 -> 144.9 | AF35: =SUM(AF4:AF33) -> 0
F36: =F35/D35 -> 0.92900068 | H36: =H35/D35 -> 0.11226377 | J36: =J35/D35 -> 71.878994 | L36: =L35/D35 -> 89.541808 | N36: =N35/D35 -> 0.301414 | R36: =R35/D35*100 -> 34.016315 | T36: =T35/D35*100 -> 19.646499 | X36: =X35/D35 -> 2.0187084

Sheet Diagnostic
A1: DIAGNOSTIC AVANCÉ - APPORTS vs BESOINS
A3: Indicateur | B3: Apport ration | C3: Besoin | D3: Couverture % | E3: Diagnostic
A4: MS | B4: ='Ration Formulation'!D35 -> 14.71 | C4: =AVERAGE('Besoins INRAE'!B26,'Besoins INRAE'!B27) -> 19.978459 | D4: =IFERROR(B4/C4*100,"") -> 73.629304 | E4: =IF(D4="","",IF(D4<95,"DEFICIT",IF(D4>115,"EXCES","OK"))) -> DEFICIT
A5: UFL | B5: ='Ration Formulation'!F35 -> 13.6656 | C5: ='Besoins INRAE'!B34 -> 18.069226 | D5: =IFERROR(B5/C5*100,"") -> 75.62914 | E5: =IF(D5="","",IF(D5<95,"DEFICIT",IF(D5>115,"EXCES","OK"))) -> DEFICIT
